Workbook

Sheet Setup
A1: Sophie — Weekly Tip-Out Tool
A3: Week Starting (Monday) | B3: 46300
A5: Server → Bar (% of server svc) | B5: 0.15
A6: Server → Support (% of server svc) | B6: 0.12
A7: Upstairs Bart → Support (% of bar svc) | B7: 0.12
A8: Server & Up-Bart → Support (% of TIPS) | B8: 0.05
A9: Tipped cash wage ($/hr) | B9: 2.13
A10: Min wage floor ($/hr) | B10: 7.25 | C10: ← min wage (wage-check reference)
A12: • Auto-filled from Toast by JOB TITLE — EVERY server, bartender, and support person who clocked in is pulled in automatically. New hires appear with no list to maintain.
A13: • Bartender venue (upstairs vs downstairs): (1) where they rang their own sales that night (Toast revenue center 'Bar' = downstairs), then (2) the only bar open that night, then (3) their home roster, then (4) default upstairs. So a bartender is put where they actually worked that night; the home roster is just the fallback for shifts where they only clocked hours. ORANGE name cells = auto-placed and unconfirmed — verify U vs D. Tell us a regular's home bar and we add them to the roster.
A14: • MISSING SOMEONE? That should be rare now — but yellow rows still let the manager add anyone who never clocked in (used the shared bar login). Enter name + hours and the day's pool re-splits for everyone; then type the same name into a yellow row on the Summary tab so it rolls up for the week.
A15: • Servers & UPSTAIRS bartenders tip 5% of their TIPS to support (they keep 95% of tips). DOWNSTAIRS bartenders do NOT tip out tips — instead they tip 5% of downstairs NET SALES to support and keep 100% of their service charge + tips. Service-charge tip-outs unchanged (15% server→bar, 12% server→support, 12% upstairs-bar→support).
A16: • Support pool = upstairs (12% of service charges + 5% of tips) + downstairs (5% of net sales), split so SA/barbacks/runner get the same $/hr each day.
A17: • Anthony Aleman (manager) — SPECIAL DEAL: on any shift where he has a service charge or tips, he keeps 100% of his own service charge + tips and tips out to NO ONE (no bar, no support). He shows on the 'Mgr (keeps own)' line under the servers; his sales do NOT feed the bar or support pools.
A18: • Every auto cell is editable — override anything that looks off.

Sheet Mon
A1: Day | B1: Monday | D1: Date | E1: 46300
A2: ⚠ DOWNSTAIRS-ONLY NIGHT — upstairs was closed. The downstairs sales & tip-out below are for this night (manager: enter the downstairs bartenders + hours).
A3: DAILY → | B3: Upstairs NET sales | D3: Downstairs NET sales | F3: Upstairs pool | H3: Downstairs pool | J3: Support pool | L3: Support $/hr
B4: 0 | D4: 998.72 | F4: =K23 -> 0 | H4: =K40 -> 315.904 | J4: =E55 -> 49.936 | L4: =IF(SUM(D57:D66)=0,0,2.13+E55/SUM(D57:D66)) -> 0
A6: SECTION 1 — UPSTAIRS
A7: Servers (auto from Toast — editable)
A8: # | B8: Name | C8: Role | D8: Hours | E8: Tips | F8: Svc Chg | G8: → Bar 15% | H8: → Sup 12% (svc) | I8: → Sup 5% (tips) | M8: Take-Home
A9: 1 | C9: Server | G9: =0.15*F9 -> 0 | H9: =0.12*F9 -> 0 | I9: =0.05*E9 -> 0 | M9: =E9+F9-G9-H9-I9 -> 0
A10: 2 | C10: Server | G10: =0.15*F10 -> 0 | H10: =0.12*F10 -> 0 | I10: =0.05*E10 -> 0 | M10: =E10+F10-G10-H10-I10 -> 0
A11: 3 | C11: Server | G11: =0.15*F11 -> 0 | H11: =0.12*F11 -> 0 | I11: =0.05*E11 -> 0 | M11: =E11+F11-G11-H11-I11 -> 0
A12: 4 | C12: Server | G12: =0.15*F12 -> 0 | H12: =0.12*F12 -> 0 | I12: =0.05*E12 -> 0 | M12: =E12+F12-G12-H12-I12 -> 0
A13: 5 | C13: Server | G13: =0.15*F13 -> 0 | H13: =0.12*F13 -> 0 | I13: =0.05*E13 -> 0 | M13: =E13+F13-G13-H13-I13 -> 0
A14: 6 | C14: Server | G14: =0.15*F14 -> 0 | H14: =0.12*F14 -> 0 | I14: =0.05*E14 -> 0 | M14: =E14+F14-G14-H14-I14 -> 0
A15: 7 | C15: Server | G15: =0.15*F15 -> 0 | H15: =0.12*F15 -> 0 | I15: =0.05*E15 -> 0 | M15: =E15+F15-G15-H15-I15 -> 0
A16: 8 | C16: Server | G16: =0.15*F16 -> 0 | H16: =0.12*F16 -> 0 | I16: =0.05*E16 -> 0 | M16: =E16+F16-G16-H16-I16 -> 0
A17: 9 | C17: Server | G17: =0.15*F17 -> 0 | H17: =0.12*F17 -> 0 | I17: =0.05*E17 -> 0 | M17: =E17+F17-G17-H17-I17 -> 0
A18: 10 | C18: Server | G18: =0.15*F18 -> 0 | H18: =0.12*F18 -> 0 | I18: =0.05*E18 -> 0 | M18: =E18+F18-G18-H18-I18 -> 0
A19: 11 | C19: Server | G19: =0.15*F19 -> 0 | H19: =0.12*F19 -> 0 | I19: =0.05*E19 -> 0 | M19: =E19+F19-G19-H19-I19 -> 0
A20: 12 | C20: Server | G20: =0.15*F20 -> 0 | H20: =0.12*F20 -> 0 | I20: =0.05*E20 -> 0 | M20: =E20+F20-G20-H20-I20 -> 0
C21: TOTAL | D21: =SUM(D9:D20) -> 0 | E21: =SUM(E9:E20) -> 0 | F21: =SUM(F9:F20) -> 0 | G21: =SUM(G9:G20) -> 0 | H21: =SUM(H9:H20) -> 0 | I21: =SUM(I9:I20) -> 0 | M21: =SUM(M9:M20) -> 0
B22: Manager (no tipped shift this day)
A23: Upstairs Bartenders | B23: (all auto-pulled from Toast; orange = verify U/D; yellow = add someone who didn't clock in) | D23: Bar svc (auto) | E23: 0 | F23: Bar tips | G23: 0 | H23: →Support 12% svc + 5% tips | I23: =0.12*E23+0.05*G23 -> 0 | J23: Pool→ | K23: =0.88*E23+0.15*F21+0.95*G23 -> 0
A24: # | B24: Name | C24: Role | D24: Hours | L24: Avg $/hr | M24: Take-Home
A25: 1 | B25: Alexanda | C25: Bartender (U) | D25: 4.92 | L25: =IF(D25=0,"",2.13+M25/D25) -> 2.13 | M25: =IF(SUM($D$25:$D$36)=0,0,$K$23*D25/SUM($D$25:$D$36)) -> 0
A26: 2 | B26: izzy | C26: Bartender (U?) | D26: 4.26 | L26: =IF(D26=0,"",2.13+M26/D26) -> 2.13 | M26: =IF(SUM($D$25:$D$36)=0,0,$K$23*D26/SUM($D$25:$D$36)) -> 0
A27: 3 | C27: Bartender (U) | L27: =IF(D27=0,"",2.13+M27/D27) | M27: =IF(SUM($D$25:$D$36)=0,0,$K$23*D27/SUM($D$25:$D$36)) -> 0
A28: 4 | C28: Bartender (U) | L28: =IF(D28=0,"",2.13+M28/D28) | M28: =IF(SUM($D$25:$D$36)=0,0,$K$23*D28/SUM($D$25:$D$36)) -> 0
A29: 5 | C29: Bartender (U) | L29: =IF(D29=0,"",2.13+M29/D29) | M29: =IF(SUM($D$25:$D$36)=0,0,$K$23*D29/SUM($D$25:$D$36)) -> 0
A30: 6 | C30: Bartender (U) | L30: =IF(D30=0,"",2.13+M30/D30) | M30: =IF(SUM($D$25:$D$36)=0,0,$K$23*D30/SUM($D$25:$D$36)) -> 0
A31: 7 | C31: Bartender (U) | L31: =IF(D31=0,"",2.13+M31/D31) | M31: =IF(SUM($D$25:$D$36)=0,0,$K$23*D31/SUM($D$25:$D$36)) -> 0
A32: 8 | C32: Bartender (U) | L32: =IF(D32=0,"",2.13+M32/D32) | M32: =IF(SUM($D$25:$D$36)=0,0,$K$23*D32/SUM($D$25:$D$36)) -> 0
A33: 9 | C33: Bartender (U) | L33: =IF(D33=0,"",2.13+M33/D33) | M33: =IF(SUM($D$25:$D$36)=0,0,$K$23*D33/SUM($D$25:$D$36)) -> 0
A34: 10 | C34: Bartender (U) | L34: =IF(D34=0,"",2.13+M34/D34) | M34: =IF(SUM($D$25:$D$36)=0,0,$K$23*D34/SUM($D$25:$D$36)) -> 0
A35: 11 | C35: Bartender (U) | L35: =IF(D35=0,"",2.13+M35/D35) | M35: =IF(SUM($D$25:$D$36)=0,0,$K$23*D35/SUM($D$25:$D$36)) -> 0
A36: 12 | C36: Bartender (U) | L36: =IF(D36=0,"",2.13+M36/D36) | M36: =IF(SUM($D$25:$D$36)=0,0,$K$23*D36/SUM($D$25:$D$36)) -> 0
C37: TOTAL | D37: =SUM(D25:D36) -> 9.18 | L37: =IF(D37=0,"",2.13+M37/D37) -> 2.13 | M37: =SUM(M25:M36) -> 0
A39: SECTION 2 — DOWNSTAIRS (auto-pulled from Toast; orange = verify U/D; yellow = add an under-clocked bartender)
D40: Bar svc (auto) | E40: 198.9 | F40: tips | G40: 166.94 | H40: →Support 5% of net sales | I40: =MIN(0.05*D4,E40+G40) -> 49.936 | J40: Pool→ | K40: =E40+G40-I40 -> 315.904
A41: # | B41: Name | C41: Role | D41: Hours | L41: Avg $/hr | M41: Take-Home
A42: 1 | C42: Bartender (D) | L42: =IF(D42=0,"",2.13+M42/D42) | M42: =IF(SUM($D$42:$D$51)=0,0,$K$40*D42/SUM($D$42:$D$51)) -> 0
...

Sheet Tue
A1: Day | B1: Tuesday | D1: Date | E1: 46301
A3: DAILY → | B3: Upstairs NET sales | D3: Downstairs NET sales | F3: Upstairs pool | H3: Downstairs pool | J3: Support pool | L3: Support $/hr
B4: 233.54 | D4: 709.93 | F4: =K23 -> 17.122 | H4: =K40 -> 2982.5335 | J4: =E55 -> 47.2165 | L4: =IF(SUM(D57:D66)=0,0,2.13+E55/SUM(D57:D66)) -> 8.3508827
A6: SECTION 1 — UPSTAIRS
A7: Servers (auto from Toast — editable)
A8: # | B8: Name | C8: Role | D8: Hours | E8: Tips | F8: Svc Chg | G8: → Bar 15% | H8: → Sup 12% (svc) | I8: → Sup 5% (tips) | M8: Take-Home
A9: 1 | B9: Valentin, Dennys | C9: Server | D9: 6.29 | E9: 35.2 | F9: 76.6 | G9: =0.15*F9 -> 11.49 | H9: =0.12*F9 -> 9.192 | I9: =0.05*E9 -> 1.76 | M9: =E9+F9-G9-H9-I9 -> 89.358
A10: 2 | C10: Server | G10: =0.15*F10 -> 0 | H10: =0.12*F10 -> 0 | I10: =0.05*E10 -> 0 | M10: =E10+F10-G10-H10-I10 -> 0
A11: 3 | C11: Server | G11: =0.15*F11 -> 0 | H11: =0.12*F11 -> 0 | I11: =0.05*E11 -> 0 | M11: =E11+F11-G11-H11-I11 -> 0
A12: 4 | C12: Server | G12: =0.15*F12 -> 0 | H12: =0.12*F12 -> 0 | I12: =0.05*E12 -> 0 | M12: =E12+F12-G12-H12-I12 -> 0
A13: 5 | C13: Server | G13: =0.15*F13 -> 0 | H13: =0.12*F13 -> 0 | I13: =0.05*E13 -> 0 | M13: =E13+F13-G13-H13-I13 -> 0
A14: 6 | C14: Server | G14: =0.15*F14 -> 0 | H14: =0.12*F14 -> 0 | I14: =0.05*E14 -> 0 | M14: =E14+F14-G14-H14-I14 -> 0
A15: 7 | C15: Server | G15: =0.15*F15 -> 0 | H15: =0.12*F15 -> 0 | I15: =0.05*E15 -> 0 | M15: =E15+F15-G15-H15-I15 -> 0
A16: 8 | C16: Server | G16: =0.15*F16 -> 0 | H16: =0.12*F16 -> 0 | I16: =0.05*E16 -> 0 | M16: =E16+F16-G16-H16-I16 -> 0
A17: 9 | C17: Server | G17: =0.15*F17 -> 0 | H17: =0.12*F17 -> 0 | I17: =0.05*E17 -> 0 | M17: =E17+F17-G17-H17-I17 -> 0
A18: 10 | C18: Server | G18: =0.15*F18 -> 0 | H18: =0.12*F18 -> 0 | I18: =0.05*E18 -> 0 | M18: =E18+F18-G18-H18-I18 -> 0
A19: 11 | C19: Server | G19: =0.15*F19 -> 0 | H19: =0.12*F19 -> 0 | I19: =0.05*E19 -> 0 | M19: =E19+F19-G19-H19-I19 -> 0
A20: 12 | C20: Server | G20: =0.15*F20 -> 0 | H20: =0.12*F20 -> 0 | I20: =0.05*E20 -> 0 | M20: =E20+F20-G20-H20-I20 -> 0
C21: TOTAL | D21: =SUM(D9:D20) -> 6.29 | E21: =SUM(E9:E20) -> 35.2 | F21: =SUM(F9:F20) -> 76.6 | G21: =SUM(G9:G20) -> 11.49 | H21: =SUM(H9:H20) -> 9.192 | I21: =SUM(I9:I20) -> 1.76 | M21: =SUM(M9:M20) -> 89.358
B22: Manager (no tipped shift this day)
A23: Upstairs Bartenders | B23: (all auto-pulled from Toast; orange = verify U/D; yellow = add someone who didn't clock in) | D23: Bar svc (auto) | E23: 6.4 | F23: Bar tips | G23: 0 | H23: →Support 12% svc + 5% tips | I23: =0.12*E23+0.05*G23 -> 0.768 | J23: Pool→ | K23: =0.88*E23+0.15*F21+0.95*G23 -> 17.122
A24: # | B24: Name | C24: Role | D24: Hours | L24: Avg $/hr | M24: Take-Home
A25: 1 | B25: Kyle | C25: Bartender (U?) | D25: 12.28 | L25: =IF(D25=0,"",2.13+M25/D25) -> 3.5242997 | M25: =IF(SUM($D$25:$D$36)=0,0,$K$23*D25/SUM($D$25:$D$36)) -> 17.122
A26: 2 | C26: Bartender (U) | L26: =IF(D26=0,"",2.13+M26/D26) | M26: =IF(SUM($D$25:$D$36)=0,0,$K$23*D26/SUM($D$25:$D$36)) -> 0
A27: 3 | C27: Bartender (U) | L27: =IF(D27=0,"",2.13+M27/D27) | M27: =IF(SUM($D$25:$D$36)=0,0,$K$23*D27/SUM($D$25:$D$36)) -> 0
A28: 4 | C28: Bartender (U) | L28: =IF(D28=0,"",2.13+M28/D28) | M28: =IF(SUM($D$25:$D$36)=0,0,$K$23*D28/SUM($D$25:$D$36)) -> 0
A29: 5 | C29: Bartender (U) | L29: =IF(D29=0,"",2.13+M29/D29) | M29: =IF(SUM($D$25:$D$36)=0,0,$K$23*D29/SUM($D$25:$D$36)) -> 0
A30: 6 | C30: Bartender (U) | L30: =IF(D30=0,"",2.13+M30/D30) | M30: =IF(SUM($D$25:$D$36)=0,0,$K$23*D30/SUM($D$25:$D$36)) -> 0
A31: 7 | C31: Bartender (U) | L31: =IF(D31=0,"",2.13+M31/D31) | M31: =IF(SUM($D$25:$D$36)=0,0,$K$23*D31/SUM($D$25:$D$36)) -> 0
A32: 8 | C32: Bartender (U) | L32: =IF(D32=0,"",2.13+M32/D32) | M32: =IF(SUM($D$25:$D$36)=0,0,$K$23*D32/SUM($D$25:$D$36)) -> 0
A33: 9 | C33: Bartender (U) | L33: =IF(D33=0,"",2.13+M33/D33) | M33: =IF(SUM($D$25:$D$36)=0,0,$K$23*D33/SUM($D$25:$D$36)) -> 0
A34: 10 | C34: Bartender (U) | L34: =IF(D34=0,"",2.13+M34/D34) | M34: =IF(SUM($D$25:$D$36)=0,0,$K$23*D34/SUM($D$25:$D$36)) -> 0
A35: 11 | C35: Bartender (U) | L35: =IF(D35=0,"",2.13+M35/D35) | M35: =IF(SUM($D$25:$D$36)=0,0,$K$23*D35/SUM($D$25:$D$36)) -> 0
A36: 12 | C36: Bartender (U) | L36: =IF(D36=0,"",2.13+M36/D36) | M36: =IF(SUM($D$25:$D$36)=0,0,$K$23*D36/SUM($D$25:$D$36)) -> 0
C37: TOTAL | D37: =SUM(D25:D36) -> 12.28 | L37: =IF(D37=0,"",2.13+M37/D37) -> 3.5242997 | M37: =SUM(M25:M36) -> 17.122
A39: SECTION 2 — DOWNSTAIRS (auto-pulled from Toast; orange = verify U/D; yellow = add an under-clocked bartender)
D40: Bar svc (auto) | E40: 816.4 | F40: tips | G40: 2201.63 | H40: →Support 5% of net sales | I40: =MIN(0.05*D4,E40+G40) -> 35.4965 | J40: Pool→ | K40: =E40+G40-I40 -> 2982.5335
A41: # | B41: Name | C41: Role | D41: Hours | L41: Avg $/hr | M41: Take-Home
A42: 1 | B42: Ferrell, Sarah | C42: Bartender (D) | D42: 7.15 | L42: =IF(D42=0,"",2.13+M42/D42) -> 419.26755 | M42: =IF(SUM($D$42:$D$51)=0,0,$K$40*D42/SUM($D$42:$D$51)) -> 2982.5335
A43: 2 | C43: Bartender (D) | L43: =IF(D43=0,"",2.13+M43/D43) | M43: =IF(SUM($D$42:$D$51)=0,0,$K$40*D43/SUM($D$42:$D$51)) -> 0
...

Sheet Wed
A1: Day | B1: Wednesday | D1: Date | E1: 46302
A3: DAILY → | B3: Upstairs NET sales | D3: Downstairs NET sales | F3: Upstairs pool | H3: Downstairs pool | J3: Support pool | L3: Support $/hr
B4: 496.46 | D4: 76.36 | F4: =K23 -> 44.661 | H4: =K40 -> 0 | J4: =E55 -> 16.1205 | L4: =IF(SUM(D57:D66)=0,0,2.13+E55/SUM(D57:D66)) -> 0
A6: SECTION 1 — UPSTAIRS
A7: Servers (auto from Toast — editable)
A8: # | B8: Name | C8: Role | D8: Hours | E8: Tips | F8: Svc Chg | G8: → Bar 15% | H8: → Sup 12% (svc) | I8: → Sup 5% (tips) | M8: Take-Home
A9: 1 | B9: Valentin, Dennys | C9: Server | D9: 5.04 | E9: 41.71 | F9: 82.8 | G9: =0.15*F9 -> 12.42 | H9: =0.12*F9 -> 9.936 | I9: =0.05*E9 -> 2.0855 | M9: =E9+F9-G9-H9-I9 -> 100.0685
A10: 2 | C10: Server | G10: =0.15*F10 -> 0 | H10: =0.12*F10 -> 0 | I10: =0.05*E10 -> 0 | M10: =E10+F10-G10-H10-I10 -> 0
A11: 3 | C11: Server | G11: =0.15*F11 -> 0 | H11: =0.12*F11 -> 0 | I11: =0.05*E11 -> 0 | M11: =E11+F11-G11-H11-I11 -> 0
A12: 4 | C12: Server | G12: =0.15*F12 -> 0 | H12: =0.12*F12 -> 0 | I12: =0.05*E12 -> 0 | M12: =E12+F12-G12-H12-I12 -> 0
A13: 5 | C13: Server | G13: =0.15*F13 -> 0 | H13: =0.12*F13 -> 0 | I13: =0.05*E13 -> 0 | M13: =E13+F13-G13-H13-I13 -> 0
A14: 6 | C14: Server | G14: =0.15*F14 -> 0 | H14: =0.12*F14 -> 0 | I14: =0.05*E14 -> 0 | M14: =E14+F14-G14-H14-I14 -> 0
A15: 7 | C15: Server | G15: =0.15*F15 -> 0 | H15: =0.12*F15 -> 0 | I15: =0.05*E15 -> 0 | M15: =E15+F15-G15-H15-I15 -> 0
A16: 8 | C16: Server | G16: =0.15*F16 -> 0 | H16: =0.12*F16 -> 0 | I16: =0.05*E16 -> 0 | M16: =E16+F16-G16-H16-I16 -> 0
A17: 9 | C17: Server | G17: =0.15*F17 -> 0 | H17: =0.12*F17 -> 0 | I17: =0.05*E17 -> 0 | M17: =E17+F17-G17-H17-I17 -> 0
A18: 10 | C18: Server | G18: =0.15*F18 -> 0 | H18: =0.12*F18 -> 0 | I18: =0.05*E18 -> 0 | M18: =E18+F18-G18-H18-I18 -> 0
A19: 11 | C19: Server | G19: =0.15*F19 -> 0 | H19: =0.12*F19 -> 0 | I19: =0.05*E19 -> 0 | M19: =E19+F19-G19-H19-I19 -> 0
A20: 12 | C20: Server | G20: =0.15*F20 -> 0 | H20: =0.12*F20 -> 0 | I20: =0.05*E20 -> 0 | M20: =E20+F20-G20-H20-I20 -> 0
C21: TOTAL | D21: =SUM(D9:D20) -> 5.04 | E21: =SUM(E9:E20) -> 41.71 | F21: =SUM(F9:F20) -> 82.8 | G21: =SUM(G9:G20) -> 12.42 | H21: =SUM(H9:H20) -> 9.936 | I21: =SUM(I9:I20) -> 2.0855 | M21: =SUM(M9:M20) -> 100.0685
B22: Manager (no tipped shift this day)
A23: Upstairs Bartenders | B23: (all auto-pulled from Toast; orange = verify U/D; yellow = add someone who didn't clock in) | D23: Bar svc (auto) | E23: 32.6 | F23: Bar tips | G23: 3.74 | H23: →Support 12% svc + 5% tips | I23: =0.12*E23+0.05*G23 -> 4.099 | J23: Pool→ | K23: =0.88*E23+0.15*F21+0.95*G23 -> 44.661
A24: # | B24: Name | C24: Role | D24: Hours | L24: Avg $/hr | M24: Take-Home
A25: 1 | B25: Miller, Jonte | C25: Bartender (U) | D25: 4.67 | L25: =IF(D25=0,"",2.13+M25/D25) -> 11.693383 | M25: =IF(SUM($D$25:$D$36)=0,0,$K$23*D25/SUM($D$25:$D$36)) -> 44.661
A26: 2 | C26: Bartender (U) | L26: =IF(D26=0,"",2.13+M26/D26) | M26: =IF(SUM($D$25:$D$36)=0,0,$K$23*D26/SUM($D$25:$D$36)) -> 0
A27: 3 | C27: Bartender (U) | L27: =IF(D27=0,"",2.13+M27/D27) | M27: =IF(SUM($D$25:$D$36)=0,0,$K$23*D27/SUM($D$25:$D$36)) -> 0
A28: 4 | C28: Bartender (U) | L28: =IF(D28=0,"",2.13+M28/D28) | M28: =IF(SUM($D$25:$D$36)=0,0,$K$23*D28/SUM($D$25:$D$36)) -> 0
A29: 5 | C29: Bartender (U) | L29: =IF(D29=0,"",2.13+M29/D29) | M29: =IF(SUM($D$25:$D$36)=0,0,$K$23*D29/SUM($D$25:$D$36)) -> 0
A30: 6 | C30: Bartender (U) | L30: =IF(D30=0,"",2.13+M30/D30) | M30: =IF(SUM($D$25:$D$36)=0,0,$K$23*D30/SUM($D$25:$D$36)) -> 0
A31: 7 | C31: Bartender (U) | L31: =IF(D31=0,"",2.13+M31/D31) | M31: =IF(SUM($D$25:$D$36)=0,0,$K$23*D31/SUM($D$25:$D$36)) -> 0
A32: 8 | C32: Bartender (U) | L32: =IF(D32=0,"",2.13+M32/D32) | M32: =IF(SUM($D$25:$D$36)=0,0,$K$23*D32/SUM($D$25:$D$36)) -> 0
A33: 9 | C33: Bartender (U) | L33: =IF(D33=0,"",2.13+M33/D33) | M33: =IF(SUM($D$25:$D$36)=0,0,$K$23*D33/SUM($D$25:$D$36)) -> 0
A34: 10 | C34: Bartender (U) | L34: =IF(D34=0,"",2.13+M34/D34) | M34: =IF(SUM($D$25:$D$36)=0,0,$K$23*D34/SUM($D$25:$D$36)) -> 0
A35: 11 | C35: Bartender (U) | L35: =IF(D35=0,"",2.13+M35/D35) | M35: =IF(SUM($D$25:$D$36)=0,0,$K$23*D35/SUM($D$25:$D$36)) -> 0
A36: 12 | C36: Bartender (U) | L36: =IF(D36=0,"",2.13+M36/D36) | M36: =IF(SUM($D$25:$D$36)=0,0,$K$23*D36/SUM($D$25:$D$36)) -> 0
C37: TOTAL | D37: =SUM(D25:D36) -> 4.67 | L37: =IF(D37=0,"",2.13+M37/D37) -> 11.693383 | M37: =SUM(M25:M36) -> 44.661
A39: SECTION 2 — DOWNSTAIRS (auto-pulled from Toast; orange = verify U/D; yellow = add an under-clocked bartender)
D40: Bar svc (auto) | E40: 0 | F40: tips | G40: 0 | H40: →Support 5% of net sales | I40: =MIN(0.05*D4,E40+G40) -> 0 | J40: Pool→ | K40: =E40+G40-I40 -> 0
A41: # | B41: Name | C41: Role | D41: Hours | L41: Avg $/hr | M41: Take-Home
A42: 1 | B42: Hadad-Barriga, Allison | C42: Bartender (D) | D42: 2.59 | L42: =IF(D42=0,"",2.13+M42/D42) -> 2.13 | M42: =IF(SUM($D$42:$D$51)=0,0,$K$40*D42/SUM($D$42:$D$51)) -> 0
A43: 2 | C43: Bartender (D) | L43: =IF(D43=0,"",2.13+M43/D43) | M43: =IF(SUM($D$42:$D$51)=0,0,$K$40*D43/SUM($D$42:$D$51)) -> 0
...

Sheet Thu
A1: Day | B1: Thursday | D1: Date | E1: 46303
A3: DAILY → | B3: Upstairs NET sales | D3: Downstairs NET sales | F3: Upstairs pool | H3: Downstairs pool | J3: Support pool | L3: Support $/hr
B4: 612.33 | D4: 1635.64 | F4: =K23 -> 126.266 | H4: =K40 -> 488.918 | J4: =E55 -> 96.216 | L4: =IF(SUM(D57:D66)=0,0,2.13+E55/SUM(D57:D66)) -> 16.176131
A6: SECTION 1 — UPSTAIRS
A7: Servers (auto from Toast — editable)
A8: # | B8: Name | C8: Role | D8: Hours | E8: Tips | F8: Svc Chg | G8: → Bar 15% | H8: → Sup 12% (svc) | I8: → Sup 5% (tips) | M8: Take-Home
A9: 1 | C9: Server | G9: =0.15*F9 -> 0 | H9: =0.12*F9 -> 0 | I9: =0.05*E9 -> 0 | M9: =E9+F9-G9-H9-I9 -> 0
A10: 2 | C10: Server | G10: =0.15*F10 -> 0 | H10: =0.12*F10 -> 0 | I10: =0.05*E10 -> 0 | M10: =E10+F10-G10-H10-I10 -> 0
A11: 3 | C11: Server | G11: =0.15*F11 -> 0 | H11: =0.12*F11 -> 0 | I11: =0.05*E11 -> 0 | M11: =E11+F11-G11-H11-I11 -> 0
A12: 4 | C12: Server | G12: =0.15*F12 -> 0 | H12: =0.12*F12 -> 0 | I12: =0.05*E12 -> 0 | M12: =E12+F12-G12-H12-I12 -> 0
A13: 5 | C13: Server | G13: =0.15*F13 -> 0 | H13: =0.12*F13 -> 0 | I13: =0.05*E13 -> 0 | M13: =E13+F13-G13-H13-I13 -> 0
A14: 6 | C14: Server | G14: =0.15*F14 -> 0 | H14: =0.12*F14 -> 0 | I14: =0.05*E14 -> 0 | M14: =E14+F14-G14-H14-I14 -> 0
A15: 7 | C15: Server | G15: =0.15*F15 -> 0 | H15: =0.12*F15 -> 0 | I15: =0.05*E15 -> 0 | M15: =E15+F15-G15-H15-I15 -> 0
A16: 8 | C16: Server | G16: =0.15*F16 -> 0 | H16: =0.12*F16 -> 0 | I16: =0.05*E16 -> 0 | M16: =E16+F16-G16-H16-I16 -> 0
A17: 9 | C17: Server | G17: =0.15*F17 -> 0 | H17: =0.12*F17 -> 0 | I17: =0.05*E17 -> 0 | M17: =E17+F17-G17-H17-I17 -> 0
A18: 10 | C18: Server | G18: =0.15*F18 -> 0 | H18: =0.12*F18 -> 0 | I18: =0.05*E18 -> 0 | M18: =E18+F18-G18-H18-I18 -> 0
A19: 11 | C19: Server | G19: =0.15*F19 -> 0 | H19: =0.12*F19 -> 0 | I19: =0.05*E19 -> 0 | M19: =E19+F19-G19-H19-I19 -> 0
A20: 12 | C20: Server | G20: =0.15*F20 -> 0 | H20: =0.12*F20 -> 0 | I20: =0.05*E20 -> 0 | M20: =E20+F20-G20-H20-I20 -> 0
C21: TOTAL | D21: =SUM(D9:D20) -> 0 | E21: =SUM(E9:E20) -> 0 | F21: =SUM(F9:F20) -> 0 | G21: =SUM(G9:G20) -> 0 | H21: =SUM(H9:H20) -> 0 | I21: =SUM(I9:I20) -> 0 | M21: =SUM(M9:M20) -> 0
B22: Manager (no tipped shift this day)
A23: Upstairs Bartenders | B23: (all auto-pulled from Toast; orange = verify U/D; yellow = add someone who didn't clock in) | D23: Bar svc (auto) | E23: 105.7 | F23: Bar tips | G23: 35 | H23: →Support 12% svc + 5% tips | I23: =0.12*E23+0.05*G23 -> 14.434 | J23: Pool→ | K23: =0.88*E23+0.15*F21+0.95*G23 -> 126.266
A24: # | B24: Name | C24: Role | D24: Hours | L24: Avg $/hr | M24: Take-Home
A25: 1 | B25: Miller, Jonte | C25: Bartender (U) | D25: 11.86 | L25: =IF(D25=0,"",2.13+M25/D25) -> 9.4625203 | M25: =IF(SUM($D$25:$D$36)=0,0,$K$23*D25/SUM($D$25:$D$36)) -> 86.963691
A26: 2 | B26: izzy | C26: Bartender (U?) | D26: 5.36 | L26: =IF(D26=0,"",2.13+M26/D26) -> 9.4625203 | M26: =IF(SUM($D$25:$D$36)=0,0,$K$23*D26/SUM($D$25:$D$36)) -> 39.302309
A27: 3 | C27: Bartender (U) | L27: =IF(D27=0,"",2.13+M27/D27) | M27: =IF(SUM($D$25:$D$36)=0,0,$K$23*D27/SUM($D$25:$D$36)) -> 0
A28: 4 | C28: Bartender (U) | L28: =IF(D28=0,"",2.13+M28/D28) | M28: =IF(SUM($D$25:$D$36)=0,0,$K$23*D28/SUM($D$25:$D$36)) -> 0
A29: 5 | C29: Bartender (U) | L29: =IF(D29=0,"",2.13+M29/D29) | M29: =IF(SUM($D$25:$D$36)=0,0,$K$23*D29/SUM($D$25:$D$36)) -> 0
A30: 6 | C30: Bartender (U) | L30: =IF(D30=0,"",2.13+M30/D30) | M30: =IF(SUM($D$25:$D$36)=0,0,$K$23*D30/SUM($D$25:$D$36)) -> 0
A31: 7 | C31: Bartender (U) | L31: =IF(D31=0,"",2.13+M31/D31) | M31: =IF(SUM($D$25:$D$36)=0,0,$K$23*D31/SUM($D$25:$D$36)) -> 0
A32: 8 | C32: Bartender (U) | L32: =IF(D32=0,"",2.13+M32/D32) | M32: =IF(SUM($D$25:$D$36)=0,0,$K$23*D32/SUM($D$25:$D$36)) -> 0
A33: 9 | C33: Bartender (U) | L33: =IF(D33=0,"",2.13+M33/D33) | M33: =IF(SUM($D$25:$D$36)=0,0,$K$23*D33/SUM($D$25:$D$36)) -> 0
A34: 10 | C34: Bartender (U) | L34: =IF(D34=0,"",2.13+M34/D34) | M34: =IF(SUM($D$25:$D$36)=0,0,$K$23*D34/SUM($D$25:$D$36)) -> 0
A35: 11 | C35: Bartender (U) | L35: =IF(D35=0,"",2.13+M35/D35) | M35: =IF(SUM($D$25:$D$36)=0,0,$K$23*D35/SUM($D$25:$D$36)) -> 0
A36: 12 | C36: Bartender (U) | L36: =IF(D36=0,"",2.13+M36/D36) | M36: =IF(SUM($D$25:$D$36)=0,0,$K$23*D36/SUM($D$25:$D$36)) -> 0
C37: TOTAL | D37: =SUM(D25:D36) -> 17.22 | L37: =IF(D37=0,"",2.13+M37/D37) -> 9.4625203 | M37: =SUM(M25:M36) -> 126.266
A39: SECTION 2 — DOWNSTAIRS (auto-pulled from Toast; orange = verify U/D; yellow = add an under-clocked bartender)
D40: Bar svc (auto) | E40: 330.8 | F40: tips | G40: 239.9 | H40: →Support 5% of net sales | I40: =MIN(0.05*D4,E40+G40) -> 81.782 | J40: Pool→ | K40: =E40+G40-I40 -> 488.918
A41: # | B41: Name | C41: Role | D41: Hours | L41: Avg $/hr | M41: Take-Home
A42: 1 | B42: white, jamie | C42: Bartender (D) | D42: 7.91 | L42: =IF(D42=0,"",2.13+M42/D42) -> 63.940114 | M42: =IF(SUM($D$42:$D$51)=0,0,$K$40*D42/SUM($D$42:$D$51)) -> 488.918
A43: 2 | C43: Bartender (D) | L43: =IF(D43=0,"",2.13+M43/D43) | M43: =IF(SUM($D$42:$D$51)=0,0,$K$40*D43/SUM($D$42:$D$51)) -> 0
...

Sheet Fri
A1: Day | B1: Friday | D1: Date | E1: 46304
A3: DAILY → | B3: Upstairs NET sales | D3: Downstairs NET sales | F3: Upstairs pool | H3: Downstairs pool | J3: Support pool | L3: Support $/hr
B4: 5937.86 | D4: 2890.63 | F4: =K23 -> 567.669 | H4: =K40 -> 876.5485 | J4: =E55 -> 322.944 | L4: =IF(SUM(D57:D66)=0,0,2.13+E55/SUM(D57:D66)) -> 11.622769
A6: SECTION 1 — UPSTAIRS
A7: Servers (auto from Toast — editable)
A8: # | B8: Name | C8: Role | D8: Hours | E8: Tips | F8: Svc Chg | G8: → Bar 15% | H8: → Sup 12% (svc) | I8: → Sup 5% (tips) | M8: Take-Home
A9: 1 | B9: Amaya Parada, Karen | C9: Server | D9: 6 | E9: 130.1 | F9: 203 | G9: =0.15*F9 -> 30.45 | H9: =0.12*F9 -> 24.36 | I9: =0.05*E9 -> 6.505 | M9: =E9+F9-G9-H9-I9 -> 271.785
A10: 2 | B10: villatoro, iliana | C10: Server | D10: 5.86 | E10: 172.48 | F10: 221.9 | G10: =0.15*F10 -> 33.285 | H10: =0.12*F10 -> 26.628 | I10: =0.05*E10 -> 8.624 | M10: =E10+F10-G10-H10-I10 -> 325.843
A11: 3 | B11: Mazariego , Sayda | C11: Server | D11: 5.85 | E11: 94.04 | F11: 180.9 | G11: =0.15*F11 -> 27.135 | H11: =0.12*F11 -> 21.708 | I11: =0.05*E11 -> 4.702 | M11: =E11+F11-G11-H11-I11 -> 221.395
A12: 4 | B12: Wenzel, Hannah | C12: Server | D12: 5.63 | E12: 0 | F12: 0 | G12: =0.15*F12 -> 0 | H12: =0.12*F12 -> 0 | I12: =0.05*E12 -> 0 | M12: =E12+F12-G12-H12-I12 -> 0
A13: 5 | B13: Hanna | C13: Server | D13: 4.6 | E13: 51.57 | F13: 153.6 | G13: =0.15*F13 -> 23.04 | H13: =0.12*F13 -> 18.432 | I13: =0.05*E13 -> 2.5785 | M13: =E13+F13-G13-H13-I13 -> 161.1195
A14: 6 | B14: Manley, Henry | C14: Server | D14: 4.07 | E14: 10 | F14: 128.2 | G14: =0.15*F14 -> 19.23 | H14: =0.12*F14 -> 15.384 | I14: =0.05*E14 -> 0.5 | M14: =E14+F14-G14-H14-I14 -> 103.086
A15: 7 | C15: Server | G15: =0.15*F15 -> 0 | H15: =0.12*F15 -> 0 | I15: =0.05*E15 -> 0 | M15: =E15+F15-G15-H15-I15 -> 0
A16: 8 | C16: Server | G16: =0.15*F16 -> 0 | H16: =0.12*F16 -> 0 | I16: =0.05*E16 -> 0 | M16: =E16+F16-G16-H16-I16 -> 0
A17: 9 | C17: Server | G17: =0.15*F17 -> 0 | H17: =0.12*F17 -> 0 | I17: =0.05*E17 -> 0 | M17: =E17+F17-G17-H17-I17 -> 0
A18: 10 | C18: Server | G18: =0.15*F18 -> 0 | H18: =0.12*F18 -> 0 | I18: =0.05*E18 -> 0 | M18: =E18+F18-G18-H18-I18 -> 0
A19: 11 | C19: Server | G19: =0.15*F19 -> 0 | H19: =0.12*F19 -> 0 | I19: =0.05*E19 -> 0 | M19: =E19+F19-G19-H19-I19 -> 0
A20: 12 | C20: Server | G20: =0.15*F20 -> 0 | H20: =0.12*F20 -> 0 | I20: =0.05*E20 -> 0 | M20: =E20+F20-G20-H20-I20 -> 0
C21: TOTAL | D21: =SUM(D9:D20) -> 32.01 | E21: =SUM(E9:E20) -> 458.19 | F21: =SUM(F9:F20) -> 887.6 | G21: =SUM(G9:G20) -> 133.14 | H21: =SUM(H9:H20) -> 106.512 | I21: =SUM(I9:I20) -> 22.9095 | M21: =SUM(M9:M20) -> 1083.2285
B22: Manager (no tipped shift this day)
A23: Upstairs Bartenders | B23: (all auto-pulled from Toast; orange = verify U/D; yellow = add someone who didn't clock in) | D23: Bar svc (auto) | E23: 354.5 | F23: Bar tips | G23: 129.02 | H23: →Support 12% svc + 5% tips | I23: =0.12*E23+0.05*G23 -> 48.991 | J23: Pool→ | K23: =0.88*E23+0.15*F21+0.95*G23 -> 567.669
A24: # | B24: Name | C24: Role | D24: Hours | L24: Avg $/hr | M24: Take-Home
A25: 1 | B25: izzy | C25: Bartender (U?) | D25: 7.56 | L25: =IF(D25=0,"",2.13+M25/D25) -> 25.812478 | M25: =IF(SUM($D$25:$D$36)=0,0,$K$23*D25/SUM($D$25:$D$36)) -> 179.03953
A26: 2 | B26: Makhotkin, Daniel | C26: Bartender (U) | D26: 7.21 | L26: =IF(D26=0,"",2.13+M26/D26) -> 25.812478 | M26: =IF(SUM($D$25:$D$36)=0,0,$K$23*D26/SUM($D$25:$D$36)) -> 170.75067
A27: 3 | B27: Kyle | C27: Bartender (U?) | D27: 5.07 | L27: =IF(D27=0,"",2.13+M27/D27) -> 25.812478 | M27: =IF(SUM($D$25:$D$36)=0,0,$K$23*D27/SUM($D$25:$D$36)) -> 120.07016
A28: 4 | B28: Manley, Henry | C28: Bartender (U) | D28: 4.13 | L28: =IF(D28=0,"",2.13+M28/D28) -> 25.812478 | M28: =IF(SUM($D$25:$D$36)=0,0,$K$23*D28/SUM($D$25:$D$36)) -> 97.808635
A29: 5 | C29: Bartender (U) | L29: =IF(D29=0,"",2.13+M29/D29) | M29: =IF(SUM($D$25:$D$36)=0,0,$K$23*D29/SUM($D$25:$D$36)) -> 0
A30: 6 | C30: Bartender (U) | L30: =IF(D30=0,"",2.13+M30/D30) | M30: =IF(SUM($D$25:$D$36)=0,0,$K$23*D30/SUM($D$25:$D$36)) -> 0
A31: 7 | C31: Bartender (U) | L31: =IF(D31=0,"",2.13+M31/D31) | M31: =IF(SUM($D$25:$D$36)=0,0,$K$23*D31/SUM($D$25:$D$36)) -> 0
A32: 8 | C32: Bartender (U) | L32: =IF(D32=0,"",2.13+M32/D32) | M32: =IF(SUM($D$25:$D$36)=0,0,$K$23*D32/SUM($D$25:$D$36)) -> 0
A33: 9 | C33: Bartender (U) | L33: =IF(D33=0,"",2.13+M33/D33) | M33: =IF(SUM($D$25:$D$36)=0,0,$K$23*D33/SUM($D$25:$D$36)) -> 0
A34: 10 | C34: Bartender (U) | L34: =IF(D34=0,"",2.13+M34/D34) | M34: =IF(SUM($D$25:$D$36)=0,0,$K$23*D34/SUM($D$25:$D$36)) -> 0
A35: 11 | C35: Bartender (U) | L35: =IF(D35=0,"",2.13+M35/D35) | M35: =IF(SUM($D$25:$D$36)=0,0,$K$23*D35/SUM($D$25:$D$36)) -> 0
A36: 12 | C36: Bartender (U) | L36: =IF(D36=0,"",2.13+M36/D36) | M36: =IF(SUM($D$25:$D$36)=0,0,$K$23*D36/SUM($D$25:$D$36)) -> 0
C37: TOTAL | D37: =SUM(D25:D36) -> 23.97 | L37: =IF(D37=0,"",2.13+M37/D37) -> 25.812478 | M37: =SUM(M25:M36) -> 567.669
A39: SECTION 2 — DOWNSTAIRS (auto-pulled from Toast; orange = verify U/D; yellow = add an under-clocked bartender)
D40: Bar svc (auto) | E40: 436.6 | F40: tips | G40: 584.48 | H40: →Support 5% of net sales | I40: =MIN(0.05*D4,E40+G40) -> 144.5315 | J40: Pool→ | K40: =E40+G40-I40 -> 876.5485
A41: # | B41: Name | C41: Role | D41: Hours | L41: Avg $/hr | M41: Take-Home
A42: 1 | C42: Bartender (D) | L42: =IF(D42=0,"",2.13+M42/D42) | M42: =IF(SUM($D$42:$D$51)=0,0,$K$40*D42/SUM($D$42:$D$51)) -> 0
A43: 2 | C43: Bartender (D) | L43: =IF(D43=0,"",2.13+M43/D43) | M43: =IF(SUM($D$42:$D$51)=0,0,$K$40*D43/SUM($D$42:$D$51)) -> 0
...

Sheet Sat
A1: Day | B1: Saturday | D1: Date | E1: 46305
A3: DAILY → | B3: Upstairs NET sales | D3: Downstairs NET sales | F3: Upstairs pool | H3: Downstairs pool | J3: Support pool | L3: Support $/hr
B4: 12652.14 | D4: 8982.62 | F4: =K23 -> 2649.939 | H4: =K40 -> 3266.469 | J4: =E55 -> 885.983 | L4: =IF(SUM(D57:D66)=0,0,2.13+E55/SUM(D57:D66)) -> 27.12952
A6: SECTION 1 — UPSTAIRS
A7: Servers (auto from Toast — editable)
A8: # | B8: Name | C8: Role | D8: Hours | E8: Tips | F8: Svc Chg | G8: → Bar 15% | H8: → Sup 12% (svc) | I8: → Sup 5% (tips) | M8: Take-Home
A9: 1 | B9: Manley, Henry | C9: Server | D9: 9.81 | E9: 167.21 | F9: 270.2 | G9: =0.15*F9 -> 40.53 | H9: =0.12*F9 -> 32.424 | I9: =0.05*E9 -> 8.3605 | M9: =E9+F9-G9-H9-I9 -> 356.0955
A10: 2 | B10: Mazariego , Sayda | C10: Server | D10: 9.47 | E10: 312.25 | F10: 492.1 | G10: =0.15*F10 -> 73.815 | H10: =0.12*F10 -> 59.052 | I10: =0.05*E10 -> 15.6125 | M10: =E10+F10-G10-H10-I10 -> 655.8705
A11: 3 | B11: villatoro, iliana | C11: Server | D11: 8.33 | E11: 117.49 | F11: 209 | G11: =0.15*F11 -> 31.35 | H11: =0.12*F11 -> 25.08 | I11: =0.05*E11 -> 5.8745 | M11: =E11+F11-G11-H11-I11 -> 264.1855
A12: 4 | B12: Hanna | C12: Server | D12: 8.19 | E12: 44.79 | F12: 261.9 | G12: =0.15*F12 -> 39.285 | H12: =0.12*F12 -> 31.428 | I12: =0.05*E12 -> 2.2395 | M12: =E12+F12-G12-H12-I12 -> 233.7375
A13: 5 | B13: Amaya Parada, Karen | C13: Server | D13: 7.97 | E13: 274.02 | F13: 247.7 | G13: =0.15*F13 -> 37.155 | H13: =0.12*F13 -> 29.724 | I13: =0.05*E13 -> 13.701 | M13: =E13+F13-G13-H13-I13 -> 441.14
A14: 6 | C14: Server | G14: =0.15*F14 -> 0 | H14: =0.12*F14 -> 0 | I14: =0.05*E14 -> 0 | M14: =E14+F14-G14-H14-I14 -> 0
A15: 7 | C15: Server | G15: =0.15*F15 -> 0 | H15: =0.12*F15 -> 0 | I15: =0.05*E15 -> 0 | M15: =E15+F15-G15-H15-I15 -> 0
A16: 8 | C16: Server | G16: =0.15*F16 -> 0 | H16: =0.12*F16 -> 0 | I16: =0.05*E16 -> 0 | M16: =E16+F16-G16-H16-I16 -> 0
A17: 9 | C17: Server | G17: =0.15*F17 -> 0 | H17: =0.12*F17 -> 0 | I17: =0.05*E17 -> 0 | M17: =E17+F17-G17-H17-I17 -> 0
A18: 10 | C18: Server | G18: =0.15*F18 -> 0 | H18: =0.12*F18 -> 0 | I18: =0.05*E18 -> 0 | M18: =E18+F18-G18-H18-I18 -> 0
A19: 11 | C19: Server | G19: =0.15*F19 -> 0 | H19: =0.12*F19 -> 0 | I19: =0.05*E19 -> 0 | M19: =E19+F19-G19-H19-I19 -> 0
A20: 12 | C20: Server | G20: =0.15*F20 -> 0 | H20: =0.12*F20 -> 0 | I20: =0.05*E20 -> 0 | M20: =E20+F20-G20-H20-I20 -> 0
C21: TOTAL | D21: =SUM(D9:D20) -> 43.77 | E21: =SUM(E9:E20) -> 915.76 | F21: =SUM(F9:F20) -> 1480.9 | G21: =SUM(G9:G20) -> 222.135 | H21: =SUM(H9:H20) -> 177.708 | I21: =SUM(I9:I20) -> 45.788 | M21: =SUM(M9:M20) -> 1951.029
B22: Aleman, Anthony | C22: Mgr (keeps own) | D22: 6.25 | E22: 0 | F22: 40 | H22: special deal — keeps 100%, tips out to no one | M22: =E22+F22 -> 40
A23: Upstairs Bartenders | B23: (all auto-pulled from Toast; orange = verify U/D; yellow = add someone who didn't clock in) | D23: Bar svc (auto) | E23: 1161.4 | F23: Bar tips | G23: 1479.76 | H23: →Support 12% svc + 5% tips | I23: =0.12*E23+0.05*G23 -> 213.356 | J23: Pool→ | K23: =0.88*E23+0.15*F21+0.95*G23 -> 2649.939
A24: # | B24: Name | C24: Role | D24: Hours | L24: Avg $/hr | M24: Take-Home
A25: 1 | B25: izzy | C25: Bartender (U?) | D25: 9.74 | L25: =IF(D25=0,"",2.13+M25/D25) -> 63.471181 | M25: =IF(SUM($D$25:$D$36)=0,0,$K$23*D25/SUM($D$25:$D$36)) -> 597.4631
A26: 2 | B26: Makhotkin, Daniel | C26: Bartender (U) | D26: 9.64 | L26: =IF(D26=0,"",2.13+M26/D26) -> 63.471181 | M26: =IF(SUM($D$25:$D$36)=0,0,$K$23*D26/SUM($D$25:$D$36)) -> 591.32898
A27: 3 | B27: Alexanda | C27: Bartender (U) | D27: 8.72 | L27: =IF(D27=0,"",2.13+M27/D27) -> 63.471181 | M27: =IF(SUM($D$25:$D$36)=0,0,$K$23*D27/SUM($D$25:$D$36)) -> 534.89509
A28: 4 | B28: Miller, Jonte | C28: Bartender (U) | D28: 7.76 | L28: =IF(D28=0,"",2.13+M28/D28) -> 63.471181 | M28: =IF(SUM($D$25:$D$36)=0,0,$K$23*D28/SUM($D$25:$D$36)) -> 476.00756
A29: 5 | B29: Kyle | C29: Bartender (U?) | D29: 7.34 | L29: =IF(D29=0,"",2.13+M29/D29) -> 63.471181 | M29: =IF(SUM($D$25:$D$36)=0,0,$K$23*D29/SUM($D$25:$D$36)) -> 450.24427
A30: 6 | B30: Hanna | C30: Bartender (U?) | D30: 0 | L30: =IF(D30=0,"",2.13+M30/D30) | M30: =IF(SUM($D$25:$D$36)=0,0,$K$23*D30/SUM($D$25:$D$36)) -> 0
A31: 7 | C31: Bartender (U) | L31: =IF(D31=0,"",2.13+M31/D31) | M31: =IF(SUM($D$25:$D$36)=0,0,$K$23*D31/SUM($D$25:$D$36)) -> 0
A32: 8 | C32: Bartender (U) | L32: =IF(D32=0,"",2.13+M32/D32) | M32: =IF(SUM($D$25:$D$36)=0,0,$K$23*D32/SUM($D$25:$D$36)) -> 0
A33: 9 | C33: Bartender (U) | L33: =IF(D33=0,"",2.13+M33/D33) | M33: =IF(SUM($D$25:$D$36)=0,0,$K$23*D33/SUM($D$25:$D$36)) -> 0
A34: 10 | C34: Bartender (U) | L34: =IF(D34=0,"",2.13+M34/D34) | M34: =IF(SUM($D$25:$D$36)=0,0,$K$23*D34/SUM($D$25:$D$36)) -> 0
A35: 11 | C35: Bartender (U) | L35: =IF(D35=0,"",2.13+M35/D35) | M35: =IF(SUM($D$25:$D$36)=0,0,$K$23*D35/SUM($D$25:$D$36)) -> 0
A36: 12 | C36: Bartender (U) | L36: =IF(D36=0,"",2.13+M36/D36) | M36: =IF(SUM($D$25:$D$36)=0,0,$K$23*D36/SUM($D$25:$D$36)) -> 0
C37: TOTAL | D37: =SUM(D25:D36) -> 43.2 | L37: =IF(D37=0,"",2.13+M37/D37) -> 63.471181 | M37: =SUM(M25:M36) -> 2649.939
A39: SECTION 2 — DOWNSTAIRS (auto-pulled from Toast; orange = verify U/D; yellow = add an under-clocked bartender)
D40: Bar svc (auto) | E40: 1493.2 | F40: tips | G40: 2222.4 | H40: →Support 5% of net sales | I40: =MIN(0.05*D4,E40+G40) -> 449.131 | J40: Pool→ | K40: =E40+G40-I40 -> 3266.469
A41: # | B41: Name | C41: Role | D41: Hours | L41: Avg $/hr | M41: Take-Home
A42: 1 | C42: Bartender (D) | L42: =IF(D42=0,"",2.13+M42/D42) | M42: =IF(SUM($D$42:$D$51)=0,0,$K$40*D42/SUM($D$42:$D$51)) -> 0
A43: 2 | C43: Bartender (D) | L43: =IF(D43=0,"",2.13+M43/D43) | M43: =IF(SUM($D$42:$D$51)=0,0,$K$40*D43/SUM($D$42:$D$51)) -> 0
...

Sheet Sun
A1: Day | B1: Sunday | D1: Date | E1: 46306
A3: DAILY → | B3: Upstairs NET sales | D3: Downstairs NET sales | F3: Upstairs pool | H3: Downstairs pool | J3: Support pool | L3: Support $/hr
B4: 2253.9 | D4: 3036.44 | F4: =K23 -> 111.263 | H4: =K40 -> 1156.978 | J4: =E55 -> 209.0945 | L4: =IF(SUM(D57:D66)=0,0,2.13+E55/SUM(D57:D66)) -> 27.880554
A6: SECTION 1 — UPSTAIRS
A7: Servers (auto from Toast — editable)
A8: # | B8: Name | C8: Role | D8: Hours | E8: Tips | F8: Svc Chg | G8: → Bar 15% | H8: → Sup 12% (svc) | I8: → Sup 5% (tips) | M8: Take-Home
A9: 1 | B9: villatoro, iliana | C9: Server | D9: 5.97 | E9: 57.31 | F9: 179.4 | G9: =0.15*F9 -> 26.91 | H9: =0.12*F9 -> 21.528 | I9: =0.05*E9 -> 2.8655 | M9: =E9+F9-G9-H9-I9 -> 185.4065
A10: 2 | B10: Hanna | C10: Server | D10: 4.44 | E10: 27.12 | F10: 212.8 | G10: =0.15*F10 -> 31.92 | H10: =0.12*F10 -> 25.536 | I10: =0.05*E10 -> 1.356 | M10: =E10+F10-G10-H10-I10 -> 181.108
A11: 3 | C11: Server | G11: =0.15*F11 -> 0 | H11: =0.12*F11 -> 0 | I11: =0.05*E11 -> 0 | M11: =E11+F11-G11-H11-I11 -> 0
A12: 4 | C12: Server | G12: =0.15*F12 -> 0 | H12: =0.12*F12 -> 0 | I12: =0.05*E12 -> 0 | M12: =E12+F12-G12-H12-I12 -> 0
A13: 5 | C13: Server | G13: =0.15*F13 -> 0 | H13: =0.12*F13 -> 0 | I13: =0.05*E13 -> 0 | M13: =E13+F13-G13-H13-I13 -> 0
A14: 6 | C14: Server | G14: =0.15*F14 -> 0 | H14: =0.12*F14 -> 0 | I14: =0.05*E14 -> 0 | M14: =E14+F14-G14-H14-I14 -> 0
A15: 7 | C15: Server | G15: =0.15*F15 -> 0 | H15: =0.12*F15 -> 0 | I15: =0.05*E15 -> 0 | M15: =E15+F15-G15-H15-I15 -> 0
A16: 8 | C16: Server | G16: =0.15*F16 -> 0 | H16: =0.12*F16 -> 0 | I16: =0.05*E16 -> 0 | M16: =E16+F16-G16-H16-I16 -> 0
A17: 9 | C17: Server | G17: =0.15*F17 -> 0 | H17: =0.12*F17 -> 0 | I17: =0.05*E17 -> 0 | M17: =E17+F17-G17-H17-I17 -> 0
A18: 10 | C18: Server | G18: =0.15*F18 -> 0 | H18: =0.12*F18 -> 0 | I18: =0.05*E18 -> 0 | M18: =E18+F18-G18-H18-I18 -> 0
A19: 11 | C19: Server | G19: =0.15*F19 -> 0 | H19: =0.12*F19 -> 0 | I19: =0.05*E19 -> 0 | M19: =E19+F19-G19-H19-I19 -> 0
A20: 12 | C20: Server | G20: =0.15*F20 -> 0 | H20: =0.12*F20 -> 0 | I20: =0.05*E20 -> 0 | M20: =E20+F20-G20-H20-I20 -> 0
C21: TOTAL | D21: =SUM(D9:D20) -> 10.41 | E21: =SUM(E9:E20) -> 84.43 | F21: =SUM(F9:F20) -> 392.2 | G21: =SUM(G9:G20) -> 58.83 | H21: =SUM(H9:H20) -> 47.064 | I21: =SUM(I9:I20) -> 4.2215 | M21: =SUM(M9:M20) -> 366.5145
B22: Manager (no tipped shift this day)
A23: Upstairs Bartenders | B23: (all auto-pulled from Toast; orange = verify U/D; yellow = add someone who didn't clock in) | D23: Bar svc (auto) | E23: 43.8 | F23: Bar tips | G23: 14.62 | H23: →Support 12% svc + 5% tips | I23: =0.12*E23+0.05*G23 -> 5.987 | J23: Pool→ | K23: =0.88*E23+0.15*F21+0.95*G23 -> 111.263
A24: # | B24: Name | C24: Role | D24: Hours | L24: Avg $/hr | M24: Take-Home
A25: 1 | B25: Miller, Jonte | C25: Bartender (U) | D25: 5.88 | L25: =IF(D25=0,"",2.13+M25/D25) -> 10.695281 | M25: =IF(SUM($D$25:$D$36)=0,0,$K$23*D25/SUM($D$25:$D$36)) -> 50.363852
A26: 2 | B26: Kyle | C26: Bartender (U?) | D26: 5.43 | L26: =IF(D26=0,"",2.13+M26/D26) -> 10.695281 | M26: =IF(SUM($D$25:$D$36)=0,0,$K$23*D26/SUM($D$25:$D$36)) -> 46.509476
A27: 3 | B27: Manley, Henry | C27: Bartender (U) | D27: 1.68 | L27: =IF(D27=0,"",2.13+M27/D27) -> 10.695281 | M27: =IF(SUM($D$25:$D$36)=0,0,$K$23*D27/SUM($D$25:$D$36)) -> 14.389672
A28: 4 | C28: Bartender (U) | L28: =IF(D28=0,"",2.13+M28/D28) | M28: =IF(SUM($D$25:$D$36)=0,0,$K$23*D28/SUM($D$25:$D$36)) -> 0
A29: 5 | C29: Bartender (U) | L29: =IF(D29=0,"",2.13+M29/D29) | M29: =IF(SUM($D$25:$D$36)=0,0,$K$23*D29/SUM($D$25:$D$36)) -> 0
A30: 6 | C30: Bartender (U) | L30: =IF(D30=0,"",2.13+M30/D30) | M30: =IF(SUM($D$25:$D$36)=0,0,$K$23*D30/SUM($D$25:$D$36)) -> 0
A31: 7 | C31: Bartender (U) | L31: =IF(D31=0,"",2.13+M31/D31) | M31: =IF(SUM($D$25:$D$36)=0,0,$K$23*D31/SUM($D$25:$D$36)) -> 0
A32: 8 | C32: Bartender (U) | L32: =IF(D32=0,"",2.13+M32/D32) | M32: =IF(SUM($D$25:$D$36)=0,0,$K$23*D32/SUM($D$25:$D$36)) -> 0
A33: 9 | C33: Bartender (U) | L33: =IF(D33=0,"",2.13+M33/D33) | M33: =IF(SUM($D$25:$D$36)=0,0,$K$23*D33/SUM($D$25:$D$36)) -> 0
A34: 10 | C34: Bartender (U) | L34: =IF(D34=0,"",2.13+M34/D34) | M34: =IF(SUM($D$25:$D$36)=0,0,$K$23*D34/SUM($D$25:$D$36)) -> 0
A35: 11 | C35: Bartender (U) | L35: =IF(D35=0,"",2.13+M35/D35) | M35: =IF(SUM($D$25:$D$36)=0,0,$K$23*D35/SUM($D$25:$D$36)) -> 0
A36: 12 | C36: Bartender (U) | L36: =IF(D36=0,"",2.13+M36/D36) | M36: =IF(SUM($D$25:$D$36)=0,0,$K$23*D36/SUM($D$25:$D$36)) -> 0
C37: TOTAL | D37: =SUM(D25:D36) -> 12.99 | L37: =IF(D37=0,"",2.13+M37/D37) -> 10.695281 | M37: =SUM(M25:M36) -> 111.263
A39: SECTION 2 — DOWNSTAIRS (auto-pulled from Toast; orange = verify U/D; yellow = add an under-clocked bartender)
D40: Bar svc (auto) | E40: 825.8 | F40: tips | G40: 483 | H40: →Support 5% of net sales | I40: =MIN(0.05*D4,E40+G40) -> 151.822 | J40: Pool→ | K40: =E40+G40-I40 -> 1156.978
A41: # | B41: Name | C41: Role | D41: Hours | L41: Avg $/hr | M41: Take-Home
A42: 1 | C42: Bartender (D) | L42: =IF(D42=0,"",2.13+M42/D42) | M42: =IF(SUM($D$42:$D$51)=0,0,$K$40*D42/SUM($D$42:$D$51)) -> 0
A43: 2 | C43: Bartender (D) | L43: =IF(D43=0,"",2.13+M43/D43) | M43: =IF(SUM($D$42:$D$51)=0,0,$K$40*D43/SUM($D$42:$D$51)) -> 0
...

Sheet Summary
A1: WEEKLY SUMMARY — take-home by person (tips + service-charge distributions) | O1: Support pool (week) | P1: =Mon!E55+Tue!E55+Wed!E55+Thu!E55+Fri!E55+Sat!E55+Sun!E55 -> 1627.5105
A2: Week of | B2: =Setup!$B$3 -> 46300 | O2: Support hours (week) | P2: =Mon!D67+Tue!D67+Wed!D67+Thu!D67+Fri!D67+Sat!D67+Sun!D67 -> 92.02
O3: Support $/hr (level) | P3: =IF(P2=0,0,2.13+P1/P2) -> 19.816487
A4: Employee | B4: Hours | C4: Mon | D4: Tue | E4: Wed | F4: Thu | G4: Fri | H4: Sat | I4: Sun | J4: WEEK TAKE-HOME | K4: $/hr (incl base) | L4: Wage check
A5: Aleman, Anthony | B5: =SUMIF(Mon!$B$9:$B$67,$A5,Mon!$D$9:$D$67)+SUMIF(Tue!$B$9:$B$67,$A5,Tue!$D$9:$D$67)+SUMIF(Wed!$B$9:$B$67,$A5,Wed!$D$9:$D$67)+SUMIF(Thu!$B$9:$B$67,$A5,Thu!$D$9:$D$67)+SUMIF(Fri!$B$9:$B$67,$A5,Fri!$D$9:$D$67)+SUMIF(Sat!$B$9:$B$67,$A5,Sat!$D$9:$D$67)+SUMIF(Sun!$B$9:$B$67,$A5,Sun!$D$9:$D$67) -> 6.25 | C5: =SUMIF(Mon!$B$9:$B$52,$A5,Mon!$M$9:$M$52) -> 0 | D5: =SUMIF(Tue!$B$9:$B$52,$A5,Tue!$M$9:$M$52) -> 0 | E5: =SUMIF(Wed!$B$9:$B$52,$A5,Wed!$M$9:$M$52) -> 0 | F5: =SUMIF(Thu!$B$9:$B$52,$A5,Thu!$M$9:$M$52) -> 0 | G5: =SUMIF(Fri!$B$9:$B$52,$A5,Fri!$M$9:$M$52) -> 0 | H5: =SUMIF(Sat!$B$9:$B$52,$A5,Sat!$M$9:$M$52) -> 40 | I5: =SUMIF(Sun!$B$9:$B$52,$A5,Sun!$M$9:$M$52) -> 0 | J5: =SUM(C5:I5)+($P$3-2.13)*(SUMIF(Mon!$B$57:$B$66,$A5,Mon!$D$57:$D$66)+SUMIF(Tue!$B$57:$B$66,$A5,Tue!$D$57:$D$66)+SUMIF(Wed!$B$57:$B$66,$A5,Wed!$D$57:$D$66)+SUMIF(Thu!$B$57:$B$66,$A5,Thu!$D$57:$D$66)+SUMIF(Fri!$B$57:$B$66,$A5,Fri!$D$57:$D$66)+SUMIF(Sat!$B$57:$B$66,$A5,Sat!$D$57:$D$66)+SUMIF(Sun!$B$57:$B$66,$A5,Sun!$D$57:$D$66)) -> 40 | K5: =IF(B5=0,"",2.13+J5/B5) -> 8.53 | L5: =IF(OR(A5="",B5=0),"",IF((2.13*B5+J5)/B5>=Setup!$B$10,"OK","SHORTFALL")) -> OK
A6: Alex | B6: =SUMIF(Mon!$B$9:$B$67,$A6,Mon!$D$9:$D$67)+SUMIF(Tue!$B$9:$B$67,$A6,Tue!$D$9:$D$67)+SUMIF(Wed!$B$9:$B$67,$A6,Wed!$D$9:$D$67)+SUMIF(Thu!$B$9:$B$67,$A6,Thu!$D$9:$D$67)+SUMIF(Fri!$B$9:$B$67,$A6,Fri!$D$9:$D$67)+SUMIF(Sat!$B$9:$B$67,$A6,Sat!$D$9:$D$67)+SUMIF(Sun!$B$9:$B$67,$A6,Sun!$D$9:$D$67) -> 15.46 | C6: =SUMIF(Mon!$B$9:$B$52,$A6,Mon!$M$9:$M$52) -> 0 | D6: =SUMIF(Tue!$B$9:$B$52,$A6,Tue!$M$9:$M$52) -> 0 | E6: =SUMIF(Wed!$B$9:$B$52,$A6,Wed!$M$9:$M$52) -> 0 | F6: =SUMIF(Thu!$B$9:$B$52,$A6,Thu!$M$9:$M$52) -> 0 | G6: =SUMIF(Fri!$B$9:$B$52,$A6,Fri!$M$9:$M$52) -> 0 | H6: =SUMIF(Sat!$B$9:$B$52,$A6,Sat!$M$9:$M$52) -> 0 | I6: =SUMIF(Sun!$B$9:$B$52,$A6,Sun!$M$9:$M$52) -> 0 | J6: =SUM(C6:I6)+($P$3-2.13)*(SUMIF(Mon!$B$57:$B$66,$A6,Mon!$D$57:$D$66)+SUMIF(Tue!$B$57:$B$66,$A6,Tue!$D$57:$D$66)+SUMIF(Wed!$B$57:$B$66,$A6,Wed!$D$57:$D$66)+SUMIF(Thu!$B$57:$B$66,$A6,Thu!$D$57:$D$66)+SUMIF(Fri!$B$57:$B$66,$A6,Fri!$D$57:$D$66)+SUMIF(Sat!$B$57:$B$66,$A6,Sat!$D$57:$D$66)+SUMIF(Sun!$B$57:$B$66,$A6,Sun!$D$57:$D$66)) -> 273.43308 | K6: =IF(B6=0,"",2.13+J6/B6) -> 19.816487 | L6: =IF(OR(A6="",B6=0),"",IF((2.13*B6+J6)/B6>=Setup!$B$10,"OK","SHORTFALL")) -> OK
A7: Alexanda | B7: =SUMIF(Mon!$B$9:$B$67,$A7,Mon!$D$9:$D$67)+SUMIF(Tue!$B$9:$B$67,$A7,Tue!$D$9:$D$67)+SUMIF(Wed!$B$9:$B$67,$A7,Wed!$D$9:$D$67)+SUMIF(Thu!$B$9:$B$67,$A7,Thu!$D$9:$D$67)+SUMIF(Fri!$B$9:$B$67,$A7,Fri!$D$9:$D$67)+SUMIF(Sat!$B$9:$B$67,$A7,Sat!$D$9:$D$67)+SUMIF(Sun!$B$9:$B$67,$A7,Sun!$D$9:$D$67) -> 13.64 | C7: =SUMIF(Mon!$B$9:$B$52,$A7,Mon!$M$9:$M$52) -> 0 | D7: =SUMIF(Tue!$B$9:$B$52,$A7,Tue!$M$9:$M$52) -> 0 | E7: =SUMIF(Wed!$B$9:$B$52,$A7,Wed!$M$9:$M$52) -> 0 | F7: =SUMIF(Thu!$B$9:$B$52,$A7,Thu!$M$9:$M$52) -> 0 | G7: =SUMIF(Fri!$B$9:$B$52,$A7,Fri!$M$9:$M$52) -> 0 | H7: =SUMIF(Sat!$B$9:$B$52,$A7,Sat!$M$9:$M$52) -> 534.89509 | I7: =SUMIF(Sun!$B$9:$B$52,$A7,Sun!$M$9:$M$52) -> 0 | J7: =SUM(C7:I7)+($P$3-2.13)*(SUMIF(Mon!$B$57:$B$66,$A7,Mon!$D$57:$D$66)+SUMIF(Tue!$B$57:$B$66,$A7,Tue!$D$57:$D$66)+SUMIF(Wed!$B$57:$B$66,$A7,Wed!$D$57:$D$66)+SUMIF(Thu!$B$57:$B$66,$A7,Thu!$D$57:$D$66)+SUMIF(Fri!$B$57:$B$66,$A7,Fri!$D$57:$D$66)+SUMIF(Sat!$B$57:$B$66,$A7,Sat!$D$57:$D$66)+SUMIF(Sun!$B$57:$B$66,$A7,Sun!$D$57:$D$66)) -> 534.89509 | K7: =IF(B7=0,"",2.13+J7/B7) -> 41.345183 | L7: =IF(OR(A7="",B7=0),"",IF((2.13*B7+J7)/B7>=Setup!$B$10,"OK","SHORTFALL")) -> OK
A8: Amaya Parada, Karen | B8: =SUMIF(Mon!$B$9:$B$67,$A8,Mon!$D$9:$D$67)+SUMIF(Tue!$B$9:$B$67,$A8,Tue!$D$9:$D$67)+SUMIF(Wed!$B$9:$B$67,$A8,Wed!$D$9:$D$67)+SUMIF(Thu!$B$9:$B$67,$A8,Thu!$D$9:$D$67)+SUMIF(Fri!$B$9:$B$67,$A8,Fri!$D$9:$D$67)+SUMIF(Sat!$B$9:$B$67,$A8,Sat!$D$9:$D$67)+SUMIF(Sun!$B$9:$B$67,$A8,Sun!$D$9:$D$67) -> 13.97 | C8: =SUMIF(Mon!$B$9:$B$52,$A8,Mon!$M$9:$M$52) -> 0 | D8: =SUMIF(Tue!$B$9:$B$52,$A8,Tue!$M$9:$M$52) -> 0 | E8: =SUMIF(Wed!$B$9:$B$52,$A8,Wed!$M$9:$M$52) -> 0 | F8: =SUMIF(Thu!$B$9:$B$52,$A8,Thu!$M$9:$M$52) -> 0 | G8: =SUMIF(Fri!$B$9:$B$52,$A8,Fri!$M$9:$M$52) -> 271.785 | H8: =SUMIF(Sat!$B$9:$B$52,$A8,Sat!$M$9:$M$52) -> 441.14 | I8: =SUMIF(Sun!$B$9:$B$52,$A8,Sun!$M$9:$M$52) -> 0 | J8: =SUM(C8:I8)+($P$3-2.13)*(SUMIF(Mon!$B$57:$B$66,$A8,Mon!$D$57:$D$66)+SUMIF(Tue!$B$57:$B$66,$A8,Tue!$D$57:$D$66)+SUMIF(Wed!$B$57:$B$66,$A8,Wed!$D$57:$D$66)+SUMIF(Thu!$B$57:$B$66,$A8,Thu!$D$57:$D$66)+SUMIF(Fri!$B$57:$B$66,$A8,Fri!$D$57:$D$66)+SUMIF(Sat!$B$57:$B$66,$A8,Sat!$D$57:$D$66)+SUMIF(Sun!$B$57:$B$66,$A8,Sun!$D$57:$D$66)) -> 712.925 | K8: =IF(B8=0,"",2.13+J8/B8) -> 53.16257 | L8: =IF(OR(A8="",B8=0),"",IF((2.13*B8+J8)/B8>=Setup!$B$10,"OK","SHORTFALL")) -> OK
A9: Castro, Wilmer | B9: =SUMIF(Mon!$B$9:$B$67,$A9,Mon!$D$9:$D$67)+SUMIF(Tue!$B$9:$B$67,$A9,Tue!$D$9:$D$67)+SUMIF(Wed!$B$9:$B$67,$A9,Wed!$D$9:$D$67)+SUMIF(Thu!$B$9:$B$67,$A9,Thu!$D$9:$D$67)+SUMIF(Fri!$B$9:$B$67,$A9,Fri!$D$9:$D$67)+SUMIF(Sat!$B$9:$B$67,$A9,Sat!$D$9:$D$67)+SUMIF(Sun!$B$9:$B$67,$A9,Sun!$D$9:$D$67) -> 20.48 | C9: =SUMIF(Mon!$B$9:$B$52,$A9,Mon!$M$9:$M$52) -> 0 | D9: =SUMIF(Tue!$B$9:$B$52,$A9,Tue!$M$9:$M$52) -> 0 | E9: =SUMIF(Wed!$B$9:$B$52,$A9,Wed!$M$9:$M$52) -> 0 | F9: =SUMIF(Thu!$B$9:$B$52,$A9,Thu!$M$9:$M$52) -> 0 | G9: =SUMIF(Fri!$B$9:$B$52,$A9,Fri!$M$9:$M$52) -> 0 | H9: =SUMIF(Sat!$B$9:$B$52,$A9,Sat!$M$9:$M$52) -> 0 | I9: =SUMIF(Sun!$B$9:$B$52,$A9,Sun!$M$9:$M$52) -> 0 | J9: =SUM(C9:I9)+($P$3-2.13)*(SUMIF(Mon!$B$57:$B$66,$A9,Mon!$D$57:$D$66)+SUMIF(Tue!$B$57:$B$66,$A9,Tue!$D$57:$D$66)+SUMIF(Wed!$B$57:$B$66,$A9,Wed!$D$57:$D$66)+SUMIF(Thu!$B$57:$B$66,$A9,Thu!$D$57:$D$66)+SUMIF(Fri!$B$57:$B$66,$A9,Fri!$D$57:$D$66)+SUMIF(Sat!$B$57:$B$66,$A9,Sat!$D$57:$D$66)+SUMIF(Sun!$B$57:$B$66,$A9,Sun!$D$57:$D$66)) -> 362.21925 | K9: =IF(B9=0,"",2.13+J9/B9) -> 19.816487 | L9: =IF(OR(A9="",B9=0),"",IF((2.13*B9+J9)/B9>=Setup!$B$10,"OK","SHORTFALL")) -> OK
A10: Ferrell, Sarah | B10: =SUMIF(Mon!$B$9:$B$67,$A10,Mon!$D$9:$D$67)+SUMIF(Tue!$B$9:$B$67,$A10,Tue!$D$9:$D$67)+SUMIF(Wed!$B$9:$B$67,$A10,Wed!$D$9:$D$67)+SUMIF(Thu!$B$9:$B$67,$A10,Thu!$D$9:$D$67)+SUMIF(Fri!$B$9:$B$67,$A10,Fri!$D$9:$D$67)+SUMIF(Sat!$B$9:$B$67,$A10,Sat!$D$9:$D$67)+SUMIF(Sun!$B$9:$B$67,$A10,Sun!$D$9:$D$67) -> 7.15 | C10: =SUMIF(Mon!$B$9:$B$52,$A10,Mon!$M$9:$M$52) -> 0 | D10: =SUMIF(Tue!$B$9:$B$52,$A10,Tue!$M$9:$M$52) -> 2982.5335 | E10: =SUMIF(Wed!$B$9:$B$52,$A10,Wed!$M$9:$M$52) -> 0 | F10: =SUMIF(Thu!$B$9:$B$52,$A10,Thu!$M$9:$M$52) -> 0 | G10: =SUMIF(Fri!$B$9:$B$52,$A10,Fri!$M$9:$M$52) -> 0 | H10: =SUMIF(Sat!$B$9:$B$52,$A10,Sat!$M$9:$M$52) -> 0 | I10: =SUMIF(Sun!$B$9:$B$52,$A10,Sun!$M$9:$M$52) -> 0 | J10: =SUM(C10:I10)+($P$3-2.13)*(SUMIF(Mon!$B$57:$B$66,$A10,Mon!$D$57:$D$66)+SUMIF(Tue!$B$57:$B$66,$A10,Tue!$D$57:$D$66)+SUMIF(Wed!$B$57:$B$66,$A10,Wed!$D$57:$D$66)+SUMIF(Thu!$B$57:$B$66,$A10,Thu!$D$57:$D$66)+SUMIF(Fri!$B$57:$B$66,$A10,Fri!$D$57:$D$66)+SUMIF(Sat!$B$57:$B$66,$A10,Sat!$D$57:$D$66)+SUMIF(Sun!$B$57:$B$66,$A10,Sun!$D$57:$D$66)) -> 2982.5335 | K10: =IF(B10=0,"",2.13+J10/B10) -> 419.26755 | L10: =IF(OR(A10="",B10=0),"",IF((2.13*B10+J10)/B10>=Setup!$B$10,"OK","SHORTFALL")) -> OK
A11: Hadad-Barriga, Allison | B11: =SUMIF(Mon!$B$9:$B$67,$A11,Mon!$D$9:$D$67)+SUMIF(Tue!$B$9:$B$67,$A11,Tue!$D$9:$D$67)+SUMIF(Wed!$B$9:$B$67,$A11,Wed!$D$9:$D$67)+SUMIF(Thu!$B$9:$B$67,$A11,Thu!$D$9:$D$67)+SUMIF(Fri!$B$9:$B$67,$A11,Fri!$D$9:$D$67)+SUMIF(Sat!$B$9:$B$67,$A11,Sat!$D$9:$D$67)+SUMIF(Sun!$B$9:$B$67,$A11,Sun!$D$9:$D$67) -> 2.59 | C11: =SUMIF(Mon!$B$9:$B$52,$A11,Mon!$M$9:$M$52) -> 0 | D11: =SUMIF(Tue!$B$9:$B$52,$A11,Tue!$M$9:$M$52) -> 0 | E11: =SUMIF(Wed!$B$9:$B$52,$A11,Wed!$M$9:$M$52) -> 0 | F11: =SUMIF(Thu!$B$9:$B$52,$A11,Thu!$M$9:$M$52) -> 0 | G11: =SUMIF(Fri!$B$9:$B$52,$A11,Fri!$M$9:$M$52) -> 0 | H11: =SUMIF(Sat!$B$9:$B$52,$A11,Sat!$M$9:$M$52) -> 0 | I11: =SUMIF(Sun!$B$9:$B$52,$A11,Sun!$M$9:$M$52) -> 0 | J11: =SUM(C11:I11)+($P$3-2.13)*(SUMIF(Mon!$B$57:$B$66,$A11,Mon!$D$57:$D$66)+SUMIF(Tue!$B$57:$B$66,$A11,Tue!$D$57:$D$66)+SUMIF(Wed!$B$57:$B$66,$A11,Wed!$D$57:$D$66)+SUMIF(Thu!$B$57:$B$66,$A11,Thu!$D$57:$D$66)+SUMIF(Fri!$B$57:$B$66,$A11,Fri!$D$57:$D$66)+SUMIF(Sat!$B$57:$B$66,$A11,Sat!$D$57:$D$66)+SUMIF(Sun!$B$57:$B$66,$A11,Sun!$D$57:$D$66)) -> 0 | K11: =IF(B11=0,"",2.13+J11/B11) -> 2.13 | L11: =IF(OR(A11="",B11=0),"",IF((2.13*B11+J11)/B11>=Setup!$B$10,"OK","SHORTFALL")) -> SHORTFALL
A12: Hanna | B12: =SUMIF(Mon!$B$9:$B$67,$A12,Mon!$D$9:$D$67)+SUMIF(Tue!$B$9:$B$67,$A12,Tue!$D$9:$D$67)+SUMIF(Wed!$B$9:$B$67,$A12,Wed!$D$9:$D$67)+SUMIF(Thu!$B$9:$B$67,$A12,Thu!$D$9:$D$67)+SUMIF(Fri!$B$9:$B$67,$A12,Fri!$D$9:$D$67)+SUMIF(Sat!$B$9:$B$67,$A12,Sat!$D$9:$D$67)+SUMIF(Sun!$B$9:$B$67,$A12,Sun!$D$9:$D$67) -> 17.23 | C12: =SUMIF(Mon!$B$9:$B$52,$A12,Mon!$M$9:$M$52) -> 0 | D12: =SUMIF(Tue!$B$9:$B$52,$A12,Tue!$M$9:$M$52) -> 0 | E12: =SUMIF(Wed!$B$9:$B$52,$A12,Wed!$M$9:$M$52) -> 0 | F12: =SUMIF(Thu!$B$9:$B$52,$A12,Thu!$M$9:$M$52) -> 0 | G12: =SUMIF(Fri!$B$9:$B$52,$A12,Fri!$M$9:$M$52) -> 161.1195 | H12: =SUMIF(Sat!$B$9:$B$52,$A12,Sat!$M$9:$M$52) -> 233.7375 | I12: =SUMIF(Sun!$B$9:$B$52,$A12,Sun!$M$9:$M$52) -> 181.108 | J12: =SUM(C12:I12)+($P$3-2.13)*(SUMIF(Mon!$B$57:$B$66,$A12,Mon!$D$57:$D$66)+SUMIF(Tue!$B$57:$B$66,$A12,Tue!$D$57:$D$66)+SUMIF(Wed!$B$57:$B$66,$A12,Wed!$D$57:$D$66)+SUMIF(Thu!$B$57:$B$66,$A12,Thu!$D$57:$D$66)+SUMIF(Fri!$B$57:$B$66,$A12,Fri!$D$57:$D$66)+SUMIF(Sat!$B$57:$B$66,$A12,Sat!$D$57:$D$66)+SUMIF(Sun!$B$57:$B$66,$A12,Sun!$D$57:$D$66)) -> 575.965 | K12: =IF(B12=0,"",2.13+J12/B12) -> 35.558033 | L12: =IF(OR(A12="",B12=0),"",IF((2.13*B12+J12)/B12>=Setup!$B$10,"OK","SHORTFALL")) -> OK
A13: Kyle | B13: =SUMIF(Mon!$B$9:$B$67,$A13,Mon!$D$9:$D$67)+SUMIF(Tue!$B$9:$B$67,$A13,Tue!$D$9:$D$67)+SUMIF(Wed!$B$9:$B$67,$A13,Wed!$D$9:$D$67)+SUMIF(Thu!$B$9:$B$67,$A13,Thu!$D$9:$D$67)+SUMIF(Fri!$B$9:$B$67,$A13,Fri!$D$9:$D$67)+SUMIF(Sat!$B$9:$B$67,$A13,Sat!$D$9:$D$67)+SUMIF(Sun!$B$9:$B$67,$A13,Sun!$D$9:$D$67) -> 36.97 | C13: =SUMIF(Mon!$B$9:$B$52,$A13,Mon!$M$9:$M$52) -> 0 | D13: =SUMIF(Tue!$B$9:$B$52,$A13,Tue!$M$9:$M$52) -> 17.122 | E13: =SUMIF(Wed!$B$9:$B$52,$A13,Wed!$M$9:$M$52) -> 0 | F13: =SUMIF(Thu!$B$9:$B$52,$A13,Thu!$M$9:$M$52) -> 0 | G13: =SUMIF(Fri!$B$9:$B$52,$A13,Fri!$M$9:$M$52) -> 120.07016 | H13: =SUMIF(Sat!$B$9:$B$52,$A13,Sat!$M$9:$M$52) -> 450.24427 | I13: =SUMIF(Sun!$B$9:$B$52,$A13,Sun!$M$9:$M$52) -> 46.509476 | J13: =SUM(C13:I13)+($P$3-2.13)*(SUMIF(Mon!$B$57:$B$66,$A13,Mon!$D$57:$D$66)+SUMIF(Tue!$B$57:$B$66,$A13,Tue!$D$57:$D$66)+SUMIF(Wed!$B$57:$B$66,$A13,Wed!$D$57:$D$66)+SUMIF(Thu!$B$57:$B$66,$A13,Thu!$D$57:$D$66)+SUMIF(Fri!$B$57:$B$66,$A13,Fri!$D$57:$D$66)+SUMIF(Sat!$B$57:$B$66,$A13,Sat!$D$57:$D$66)+SUMIF(Sun!$B$57:$B$66,$A13,Sun!$D$57:$D$66)) -> 755.09834 | K13: =IF(B13=0,"",2.13+J13/B13) -> 22.554624 | L13: =IF(OR(A13="",B13=0),"",IF((2.13*B13+J13)/B13>=Setup!$B$10,"OK","SHORTFALL")) -> OK
A14: Makhotkin, Daniel | B14: =SUMIF(Mon!$B$9:$B$67,$A14,Mon!$D$9:$D$67)+SUMIF(Tue!$B$9:$B$67,$A14,Tue!$D$9:$D$67)+SUMIF(Wed!$B$9:$B$67,$A14,Wed!$D$9:$D$67)+SUMIF(Thu!$B$9:$B$67,$A14,Thu!$D$9:$D$67)+SUMIF(Fri!$B$9:$B$67,$A14,Fri!$D$9:$D$67)+SUMIF(Sat!$B$9:$B$67,$A14,Sat!$D$9:$D$67)+SUMIF(Sun!$B$9:$B$67,$A14,Sun!$D$9:$D$67) -> 16.85 | C14: =SUMIF(Mon!$B$9:$B$52,$A14,Mon!$M$9:$M$52) -> 0 | D14: =SUMIF(Tue!$B$9:$B$52,$A14,Tue!$M$9:$M$52) -> 0 | E14: =SUMIF(Wed!$B$9:$B$52,$A14,Wed!$M$9:$M$52) -> 0 | F14: =SUMIF(Thu!$B$9:$B$52,$A14,Thu!$M$9:$M$52) -> 0 | G14: =SUMIF(Fri!$B$9:$B$52,$A14,Fri!$M$9:$M$52) -> 170.75067 | H14: =SUMIF(Sat!$B$9:$B$52,$A14,Sat!$M$9:$M$52) -> 591.32898 | I14: =SUMIF(Sun!$B$9:$B$52,$A14,Sun!$M$9:$M$52) -> 0 | J14: =SUM(C14:I14)+($P$3-2.13)*(SUMIF(Mon!$B$57:$B$66,$A14,Mon!$D$57:$D$66)+SUMIF(Tue!$B$57:$B$66,$A14,Tue!$D$57:$D$66)+SUMIF(Wed!$B$57:$B$66,$A14,Wed!$D$57:$D$66)+SUMIF(Thu!$B$57:$B$66,$A14,Thu!$D$57:$D$66)+SUMIF(Fri!$B$57:$B$66,$A14,Fri!$D$57:$D$66)+SUMIF(Sat!$B$57:$B$66,$A14,Sat!$D$57:$D$66)+SUMIF(Sun!$B$57:$B$66,$A14,Sun!$D$57:$D$66)) -> 762.07965 | K14: =IF(B14=0,"",2.13+J14/B14) -> 47.357279 | L14: =IF(OR(A14="",B14=0),"",IF((2.13*B14+J14)/B14>=Setup!$B$10,"OK","SHORTFALL")) -> OK
A15: Manley, Henry | B15: =SUMIF(Mon!$B$9:$B$67,$A15,Mon!$D$9:$D$67)+SUMIF(Tue!$B$9:$B$67,$A15,Tue!$D$9:$D$67)+SUMIF(Wed!$B$9:$B$67,$A15,Wed!$D$9:$D$67)+SUMIF(Thu!$B$9:$B$67,$A15,Thu!$D$9:$D$67)+SUMIF(Fri!$B$9:$B$67,$A15,Fri!$D$9:$D$67)+SUMIF(Sat!$B$9:$B$67,$A15,Sat!$D$9:$D$67)+SUMIF(Sun!$B$9:$B$67,$A15,Sun!$D$9:$D$67) -> 19.69 | C15: =SUMIF(Mon!$B$9:$B$52,$A15,Mon!$M$9:$M$52) -> 0 | D15: =SUMIF(Tue!$B$9:$B$52,$A15,Tue!$M$9:$M$52) -> 0 | E15: =SUMIF(Wed!$B$9:$B$52,$A15,Wed!$M$9:$M$52) -> 0 | F15: =SUMIF(Thu!$B$9:$B$52,$A15,Thu!$M$9:$M$52) -> 0 | G15: =SUMIF(Fri!$B$9:$B$52,$A15,Fri!$M$9:$M$52) -> 200.89463 | H15: =SUMIF(Sat!$B$9:$B$52,$A15,Sat!$M$9:$M$52) -> 356.0955 | I15: =SUMIF(Sun!$B$9:$B$52,$A15,Sun!$M$9:$M$52) -> 14.389672 | J15: =SUM(C15:I15)+($P$3-2.13)*(SUMIF(Mon!$B$57:$B$66,$A15,Mon!$D$57:$D$66)+SUMIF(Tue!$B$57:$B$66,$A15,Tue!$D$57:$D$66)+SUMIF(Wed!$B$57:$B$66,$A15,Wed!$D$57:$D$66)+SUMIF(Thu!$B$57:$B$66,$A15,Thu!$D$57:$D$66)+SUMIF(Fri!$B$57:$B$66,$A15,Fri!$D$57:$D$66)+SUMIF(Sat!$B$57:$B$66,$A15,Sat!$D$57:$D$66)+SUMIF(Sun!$B$57:$B$66,$A15,Sun!$D$57:$D$66)) -> 571.37981 | K15: =IF(B15=0,"",2.13+J15/B15) -> 31.148781 | L15: =IF(OR(A15="",B15=0),"",IF((2.13*B15+J15)/B15>=Setup!$B$10,"OK","SHORTFALL")) -> OK
A16: Mazariego , Sayda | B16: =SUMIF(Mon!$B$9:$B$67,$A16,Mon!$D$9:$D$67)+SUMIF(Tue!$B$9:$B$67,$A16,Tue!$D$9:$D$67)+SUMIF(Wed!$B$9:$B$67,$A16,Wed!$D$9:$D$67)+SUMIF(Thu!$B$9:$B$67,$A16,Thu!$D$9:$D$67)+SUMIF(Fri!$B$9:$B$67,$A16,Fri!$D$9:$D$67)+SUMIF(Sat!$B$9:$B$67,$A16,Sat!$D$9:$D$67)+SUMIF(Sun!$B$9:$B$67,$A16,Sun!$D$9:$D$67) -> 15.32 | C16: =SUMIF(Mon!$B$9:$B$52,$A16,Mon!$M$9:$M$52) -> 0 | D16: =SUMIF(Tue!$B$9:$B$52,$A16,Tue!$M$9:$M$52) -> 0 | E16: =SUMIF(Wed!$B$9:$B$52,$A16,Wed!$M$9:$M$52) -> 0 | F16: =SUMIF(Thu!$B$9:$B$52,$A16,Thu!$M$9:$M$52) -> 0 | G16: =SUMIF(Fri!$B$9:$B$52,$A16,Fri!$M$9:$M$52) -> 221.395 | H16: =SUMIF(Sat!$B$9:$B$52,$A16,Sat!$M$9:$M$52) -> 655.8705 | I16: =SUMIF(Sun!$B$9:$B$52,$A16,Sun!$M$9:$M$52) -> 0 | J16: =SUM(C16:I16)+($P$3-2.13)*(SUMIF(Mon!$B$57:$B$66,$A16,Mon!$D$57:$D$66)+SUMIF(Tue!$B$57:$B$66,$A16,Tue!$D$57:$D$66)+SUMIF(Wed!$B$57:$B$66,$A16,Wed!$D$57:$D$66)+SUMIF(Thu!$B$57:$B$66,$A16,Thu!$D$57:$D$66)+SUMIF(Fri!$B$57:$B$66,$A16,Fri!$D$57:$D$66)+SUMIF(Sat!$B$57:$B$66,$A16,Sat!$D$57:$D$66)+SUMIF(Sun!$B$57:$B$66,$A16,Sun!$D$57:$D$66)) -> 877.2655 | K16: =IF(B16=0,"",2.13+J16/B16) -> 59.392761 | L16: =IF(OR(A16="",B16=0),"",IF((2.13*B16+J16)/B16>=Setup!$B$10,"OK","SHORTFALL")) -> OK
... A25: white, jamie | B25: =SUMIF(Mon!$B$9:$B$67,$A25,Mon!$D$9:$D$67)+SUMIF(Tue!$B$9:$B$67,$A25,Tue!$D$9:$D$67)+SUMIF(Wed!$B$9:$B$67,$A25,Wed!$D$9:$D$67)+SUMIF(Thu!$B$9:$B$67,$A25,Thu!$D$9:$D$67)+SUMIF(Fri!$B$9:$B$67,$A25,Fri!$D$9:$D$67)+SUMIF(Sat!$B$9:$B$67,$A25,Sat!$D$9:$D$67)+SUMIF(Sun!$B$9:$B$67,$A25,Sun!$D$9:$D$67) -> 7.91 | C25: =SUMIF(Mon!$B$9:$B$52,$A25,Mon!$M$9:$M$52) -> 0 | D25: =SUMIF(Tue!$B$9:$B$52,$A25,Tue!$M$9:$M$52) -> 0 | E25: =SUMIF(Wed!$B$9:$B$52,$A25,Wed!$M$9:$M$52) -> 0 | F25: =SUMIF(Thu!$B$9:$B$52,$A25,Thu!$M$9:$M$52) -> 488.918 | G25: =SUMIF(Fri!$B$9:$B$52,$A25,Fri!$M$9:$M$52) -> 0 | H25: =SUMIF(Sat!$B$9:$B$52,$A25,Sat!$M$9:$M$52) -> 0 | I25: =SUMIF(Sun!$B$9:$B$52,$A25,Sun!$M$9:$M$52) -> 0 | J25: =SUM(C25:I25)+($P$3-2.13)*(SUMIF(Mon!$B$57:$B$66,$A25,Mon!$D$57:$D$66)+SUMIF(Tue!$B$57:$B$66,$A25,Tue!$D$57:$D$66)+SUMIF(Wed!$B$57:$B$66,$A25,Wed!$D$57:$D$66)+SUMIF(Thu!$B$57:$B$66,$A25,Thu!$D$57:$D$66)+SUMIF(Fri!$B$57:$B$66,$A25,Fri!$D$57:$D$66)+SUMIF(Sat!$B$57:$B$66,$A25,Sat!$D$57:$D$66)+SUMIF(Sun!$B$57:$B$66,$A25,Sun!$D$57:$D$66)) -> 488.918 | K25: =IF(B25=0,"",2.13+J25/B25) -> 63.940114 | L25: =IF(OR(A25="",B25=0),"",IF((2.13*B25+J25)/B25>=Setup!$B$10,"OK","SHORTFALL")) -> OK
B26: =SUMIF(Mon!$B$9:$B$67,$A26,Mon!$D$9:$D$67)+SUMIF(Tue!$B$9:$B$67,$A26,Tue!$D$9:$D$67)+SUMIF(Wed!$B$9:$B$67,$A26,Wed!$D$9:$D$67)+SUMIF(Thu!$B$9:$B$67,$A26,Thu!$D$9:$D$67)+SUMIF(Fri!$B$9:$B$67,$A26,Fri!$D$9:$D$67)+SUMIF(Sat!$B$9:$B$67,$A26,Sat!$D$9:$D$67)+SUMIF(Sun!$B$9:$B$67,$A26,Sun!$D$9:$D$67) -> 0 | C26: =SUMIF(Mon!$B$9:$B$52,$A26,Mon!$M$9:$M$52) -> 0 | D26: =SUMIF(Tue!$B$9:$B$52,$A26,Tue!$M$9:$M$52) -> 0 | E26: =SUMIF(Wed!$B$9:$B$52,$A26,Wed!$M$9:$M$52) -> 0 | F26: =SUMIF(Thu!$B$9:$B$52,$A26,Thu!$M$9:$M$52) -> 0 | G26: =SUMIF(Fri!$B$9:$B$52,$A26,Fri!$M$9:$M$52) -> 0 | H26: =SUMIF(Sat!$B$9:$B$52,$A26,Sat!$M$9:$M$52) -> 0 | I26: =SUMIF(Sun!$B$9:$B$52,$A26,Sun!$M$9:$M$52) -> 0 | J26: =SUM(C26:I26)+($P$3-2.13)*(SUMIF(Mon!$B$57:$B$66,$A26,Mon!$D$57:$D$66)+SUMIF(Tue!$B$57:$B$66,$A26,Tue!$D$57:$D$66)+SUMIF(Wed!$B$57:$B$66,$A26,Wed!$D$57:$D$66)+SUMIF(Thu!$B$57:$B$66,$A26,Thu!$D$57:$D$66)+SUMIF(Fri!$B$57:$B$66,$A26,Fri!$D$57:$D$66)+SUMIF(Sat!$B$57:$B$66,$A26,Sat!$D$57:$D$66)+SUMIF(Sun!$B$57:$B$66,$A26,Sun!$D$57:$D$66)) -> 0 | K26: =IF(B26=0,"",2.13+J26/B26) | L26: =IF(OR(A26="",B26=0),"",IF((2.13*B26+J26)/B26>=Setup!$B$10,"OK","SHORTFALL"))
B27: =SUMIF(Mon!$B$9:$B$67,$A27,Mon!$D$9:$D$67)+SUMIF(Tue!$B$9:$B$67,$A27,Tue!$D$9:$D$67)+SUMIF(Wed!$B$9:$B$67,$A27,Wed!$D$9:$D$67)+SUMIF(Thu!$B$9:$B$67,$A27,Thu!$D$9:$D$67)+SUMIF(Fri!$B$9:$B$67,$A27,Fri!$D$9:$D$67)+SUMIF(Sat!$B$9:$B$67,$A27,Sat!$D$9:$D$67)+SUMIF(Sun!$B$9:$B$67,$A27,Sun!$D$9:$D$67) -> 0 | C27: =SUMIF(Mon!$B$9:$B$52,$A27,Mon!$M$9:$M$52) -> 0 | D27: =SUMIF(Tue!$B$9:$B$52,$A27,Tue!$M$9:$M$52) -> 0 | E27: =SUMIF(Wed!$B$9:$B$52,$A27,Wed!$M$9:$M$52) -> 0 | F27: =SUMIF(Thu!$B$9:$B$52,$A27,Thu!$M$9:$M$52) -> 0 | G27: =SUMIF(Fri!$B$9:$B$52,$A27,Fri!$M$9:$M$52) -> 0 | H27: =SUMIF(Sat!$B$9:$B$52,$A27,Sat!$M$9:$M$52) -> 0 | I27: =SUMIF(Sun!$B$9:$B$52,$A27,Sun!$M$9:$M$52) -> 0 | J27: =SUM(C27:I27)+($P$3-2.13)*(SUMIF(Mon!$B$57:$B$66,$A27,Mon!$D$57:$D$66)+SUMIF(Tue!$B$57:$B$66,$A27,Tue!$D$57:$D$66)+SUMIF(Wed!$B$57:$B$66,$A27,Wed!$D$57:$D$66)+SUMIF(Thu!$B$57:$B$66,$A27,Thu!$D$57:$D$66)+SUMIF(Fri!$B$57:$B$66,$A27,Fri!$D$57:$D$66)+SUMIF(Sat!$B$57:$B$66,$A27,Sat!$D$57:$D$66)+SUMIF(Sun!$B$57:$B$66,$A27,Sun!$D$57:$D$66)) -> 0 | K27: =IF(B27=0,"",2.13+J27/B27) | L27: =IF(OR(A27="",B27=0),"",IF((2.13*B27+J27)/B27>=Setup!$B$10,"OK","SHORTFALL"))
B28: =SUMIF(Mon!$B$9:$B$67,$A28,Mon!$D$9:$D$67)+SUMIF(Tue!$B$9:$B$67,$A28,Tue!$D$9:$D$67)+SUMIF(Wed!$B$9:$B$67,$A28,Wed!$D$9:$D$67)+SUMIF(Thu!$B$9:$B$67,$A28,Thu!$D$9:$D$67)+SUMIF(Fri!$B$9:$B$67,$A28,Fri!$D$9:$D$67)+SUMIF(Sat!$B$9:$B$67,$A28,Sat!$D$9:$D$67)+SUMIF(Sun!$B$9:$B$67,$A28,Sun!$D$9:$D$67) -> 0 | C28: =SUMIF(Mon!$B$9:$B$52,$A28,Mon!$M$9:$M$52) -> 0 | D28: =SUMIF(Tue!$B$9:$B$52,$A28,Tue!$M$9:$M$52) -> 0 | E28: =SUMIF(Wed!$B$9:$B$52,$A28,Wed!$M$9:$M$52) -> 0 | F28: =SUMIF(Thu!$B$9:$B$52,$A28,Thu!$M$9:$M$52) -> 0 | G28: =SUMIF(Fri!$B$9:$B$52,$A28,Fri!$M$9:$M$52) -> 0 | H28: =SUMIF(Sat!$B$9:$B$52,$A28,Sat!$M$9:$M$52) -> 0 | I28: =SUMIF(Sun!$B$9:$B$52,$A28,Sun!$M$9:$M$52) -> 0 | J28: =SUM(C28:I28)+($P$3-2.13)*(SUMIF(Mon!$B$57:$B$66,$A28,Mon!$D$57:$D$66)+SUMIF(Tue!$B$57:$B$66,$A28,Tue!$D$57:$D$66)+SUMIF(Wed!$B$57:$B$66,$A28,Wed!$D$57:$D$66)+SUMIF(Thu!$B$57:$B$66,$A28,Thu!$D$57:$D$66)+SUMIF(Fri!$B$57:$B$66,$A28,Fri!$D$57:$D$66)+SUMIF(Sat!$B$57:$B$66,$A28,Sat!$D$57:$D$66)+SUMIF(Sun!$B$57:$B$66,$A28,Sun!$D$57:$D$66)) -> 0 | K28: =IF(B28=0,"",2.13+J28/B28) | L28: =IF(OR(A28="",B28=0),"",IF((2.13*B28+J28)/B28>=Setup!$B$10,"OK","SHORTFALL"))
B29: =SUMIF(Mon!$B$9:$B$67,$A29,Mon!$D$9:$D$67)+SUMIF(Tue!$B$9:$B$67,$A29,Tue!$D$9:$D$67)+SUMIF(Wed!$B$9:$B$67,$A29,Wed!$D$9:$D$67)+SUMIF(Thu!$B$9:$B$67,$A29,Thu!$D$9:$D$67)+SUMIF(Fri!$B$9:$B$67,$A29,Fri!$D$9:$D$67)+SUMIF(Sat!$B$9:$B$67,$A29,Sat!$D$9:$D$67)+SUMIF(Sun!$B$9:$B$67,$A29,Sun!$D$9:$D$67) -> 0 | C29: =SUMIF(Mon!$B$9:$B$52,$A29,Mon!$M$9:$M$52) -> 0 | D29: =SUMIF(Tue!$B$9:$B$52,$A29,Tue!$M$9:$M$52) -> 0 | E29: =SUMIF(Wed!$B$9:$B$52,$A29,Wed!$M$9:$M$52) -> 0 | F29: =SUMIF(Thu!$B$9:$B$52,$A29,Thu!$M$9:$M$52) -> 0 | G29: =SUMIF(Fri!$B$9:$B$52,$A29,Fri!$M$9:$M$52) -> 0 | H29: =SUMIF(Sat!$B$9:$B$52,$A29,Sat!$M$9:$M$52) -> 0 | I29: =SUMIF(Sun!$B$9:$B$52,$A29,Sun!$M$9:$M$52) -> 0 | J29: =SUM(C29:I29)+($P$3-2.13)*(SUMIF(Mon!$B$57:$B$66,$A29,Mon!$D$57:$D$66)+SUMIF(Tue!$B$57:$B$66,$A29,Tue!$D$57:$D$66)+SUMIF(Wed!$B$57:$B$66,$A29,Wed!$D$57:$D$66)+SUMIF(Thu!$B$57:$B$66,$A29,Thu!$D$57:$D$66)+SUMIF(Fri!$B$57:$B$66,$A29,Fri!$D$57:$D$66)+SUMIF(Sat!$B$57:$B$66,$A29,Sat!$D$57:$D$66)+SUMIF(Sun!$B$57:$B$66,$A29,Sun!$D$57:$D$66)) -> 0 | K29: =IF(B29=0,"",2.13+J29/B29) | L29: =IF(OR(A29="",B29=0),"",IF((2.13*B29+J29)/B29>=Setup!$B$10,"OK","SHORTFALL"))
